 * Serving Flask app 'app'
 * Debug mode: on
[31m[1mWARNING: This is a development server. Do not use it in a production deployment. Use a production WSGI server instead.[0m
 * Running on all addresses (0.0.0.0)
 * Running on http://127.0.0.1:5000
 * Running on http://192.168.0.28:5000
[33mPress CTRL+C to quit[0m
 * Restarting with stat
 * Debugger is active!
 * Debugger PIN: 480-715-215
192.168.0.181 - - [05/Feb/2024 21:00:47] "GET / HTTP/1.1" 200 -
192.168.0.181 - - [05/Feb/2024 21:00:47] "[33mGET /favicon.ico HTTP/1.1[0m" 404 -
192.168.0.181 - - [05/Feb/2024 21:01:06] "[35m[1mPOST / HTTP/1.1[0m" 500 -
Traceback (most recent call last):
  File "/usr/local/lib/python3.9/dist-packages/flask/app.py", line 1488, in __call__
    return self.wsgi_app(environ, start_response)
  File "/usr/local/lib/python3.9/dist-packages/flask/app.py", line 1466, in wsgi_app
    response = self.handle_exception(e)
  File "/usr/local/lib/python3.9/dist-packages/flask/app.py", line 1463, in wsgi_app
    response = self.full_dispatch_request()
  File "/usr/local/lib/python3.9/dist-packages/flask/app.py", line 872, in full_dispatch_request
    rv = self.handle_user_exception(e)
  File "/usr/local/lib/python3.9/dist-packages/flask/app.py", line 870, in full_dispatch_request
    rv = self.dispatch_request()
  File "/usr/local/lib/python3.9/dist-packages/flask/app.py", line 855, in dispatch_request
    return self.ensure_sync(self.view_functions[rule.endpoint])(**view_args)  # type: ignore[no-any-return]
  File "/root/app.py", line 15, in home
    response = openai.Completion.create(
  File "/usr/local/lib/python3.9/dist-packages/openai/lib/_old_api.py", line 39, in __call__
    raise APIRemovedInV1(symbol=self._symbol)
openai.lib._old_api.APIRemovedInV1: 

You tried to access openai.Completion, but this is no longer supported in openai>=1.0.0 - see the README at https://github.com/openai/openai-python for the API.

You can run `openai migrate` to automatically upgrade your codebase to use the 1.0.0 interface. 

Alternatively, you can pin your installation to the old version, e.g. `pip install openai==0.28`

A detailed migration guide is available here: https://github.com/openai/openai-python/discussions/742

192.168.0.181 - - [05/Feb/2024 21:01:07] "GET /?__debugger__=yes&cmd=resource&f=style.css HTTP/1.1" 200 -
192.168.0.181 - - [05/Feb/2024 21:01:07] "GET /?__debugger__=yes&cmd=resource&f=debugger.js HTTP/1.1" 200 -
192.168.0.181 - - [05/Feb/2024 21:01:07] "GET /?__debugger__=yes&cmd=resource&f=console.png HTTP/1.1" 200 -
192.168.0.181 - - [05/Feb/2024 21:01:07] "[36mGET /?__debugger__=yes&cmd=resource&f=console.png HTTP/1.1[0m" 304 -
 * Detected change in '/root/app.py', reloading
 * Restarting with stat
Traceback (most recent call last):
  File "/root/app.py", line 5, in <module>
    client = OpenAI(api_key=os.getenv('OPENAI_API_KEY'))
NameError: name 'os' is not defined
  File "/root/app.py", line 38
    return '''
IndentationError: unexpected indent
  File "/root/app.py", line 38
    return '''
IndentationError: unexpected indent
  File "/root/app.py", line 38
    return '''
IndentationError: unexpected indent
  File "/root/app.py", line 38
    return '''
IndentationError: unexpected indent
  File "/root/app.py", line 25
    return render_template_string("""
TabError: inconsistent use of tabs and spaces in indentation
  File "/root/app.py", line 25
    return render_template_string("""
TabError: inconsistent use of tabs and spaces in indentation
  File "/root/app.py", line 24
    return render_template_string("""
TabError: inconsistent use of tabs and spaces in indentation
 * Serving Flask app 'app'
 * Debug mode: on
[31m[1mWARNING: This is a development server. Do not use it in a production deployment. Use a production WSGI server instead.[0m
 * Running on all addresses (0.0.0.0)
 * Running on http://127.0.0.1:5000
 * Running on http://192.168.0.28:5000
[33mPress CTRL+C to quit[0m
 * Restarting with stat
 * Debugger is active!
 * Debugger PIN: 480-715-215
192.168.0.181 - - [05/Feb/2024 21:50:22] "GET / HTTP/1.1" 200 -
192.168.0.181 - - [05/Feb/2024 21:50:22] "[33mGET /favicon.ico HTTP/1.1[0m" 404 -
192.168.0.181 - - [05/Feb/2024 21:51:17] "[35m[1mPOST / HTTP/1.1[0m" 500 -
Traceback (most recent call last):
  File "/usr/local/lib/python3.9/dist-packages/flask/app.py", line 1488, in __call__
    return self.wsgi_app(environ, start_response)
  File "/usr/local/lib/python3.9/dist-packages/flask/app.py", line 1466, in wsgi_app
    response = self.handle_exception(e)
  File "/usr/local/lib/python3.9/dist-packages/flask/app.py", line 1463, in wsgi_app
    response = self.full_dispatch_request()
  File "/usr/local/lib/python3.9/dist-packages/flask/app.py", line 872, in full_dispatch_request
    rv = self.handle_user_exception(e)
  File "/usr/local/lib/python3.9/dist-packages/flask/app.py", line 870, in full_dispatch_request
    rv = self.dispatch_request()
  File "/usr/local/lib/python3.9/dist-packages/flask/app.py", line 855, in dispatch_request
    return self.ensure_sync(self.view_functions[rule.endpoint])(**view_args)  # type: ignore[no-any-return]
  File "/root/app.py", line 15, in home
    response = openai.Completion.create(
  File "/usr/local/lib/python3.9/dist-packages/openai/lib/_old_api.py", line 39, in __call__
    raise APIRemovedInV1(symbol=self._symbol)
openai.lib._old_api.APIRemovedInV1: 

You tried to access openai.Completion, but this is no longer supported in openai>=1.0.0 - see the README at https://github.com/openai/openai-python for the API.

You can run `openai migrate` to automatically upgrade your codebase to use the 1.0.0 interface. 

Alternatively, you can pin your installation to the old version, e.g. `pip install openai==0.28`

A detailed migration guide is available here: https://github.com/openai/openai-python/discussions/742

192.168.0.181 - - [05/Feb/2024 21:51:17] "[36mGET /?__debugger__=yes&cmd=resource&f=style.css HTTP/1.1[0m" 304 -
192.168.0.181 - - [05/Feb/2024 21:51:17] "[36mGET /?__debugger__=yes&cmd=resource&f=debugger.js HTTP/1.1[0m" 304 -
192.168.0.181 - - [05/Feb/2024 21:51:18] "[36mGET /?__debugger__=yes&cmd=resource&f=console.png HTTP/1.1[0m" 304 -
192.168.0.181 - - [05/Feb/2024 21:51:18] "[36mGET /?__debugger__=yes&cmd=resource&f=console.png HTTP/1.1[0m" 304 -
 * Detected change in '/root/app.py', reloading
 * Restarting with stat
Traceback (most recent call last):
  File "/root/app.py", line 4, in <module>
    client = OpenAI(api_key=os.getenv("OPENAI_API_KEY"))
NameError: name 'os' is not defined
 * Serving Flask app 'app'
 * Debug mode: on
[31m[1mWARNING: This is a development server. Do not use it in a production deployment. Use a production WSGI server instead.[0m
 * Running on all addresses (0.0.0.0)
 * Running on http://127.0.0.1:5000
 * Running on http://192.168.0.28:5000
[33mPress CTRL+C to quit[0m
 * Restarting with stat
 * Debugger is active!
 * Debugger PIN: 480-715-215
192.168.0.181 - - [05/Feb/2024 21:56:37] "GET / HTTP/1.1" 200 -
192.168.0.181 - - [05/Feb/2024 21:56:41] "[35m[1mPOST / HTTP/1.1[0m" 500 -
Traceback (most recent call last):
  File "/usr/local/lib/python3.9/dist-packages/flask/app.py", line 1488, in __call__
    return self.wsgi_app(environ, start_response)
  File "/usr/local/lib/python3.9/dist-packages/flask/app.py", line 1466, in wsgi_app
    response = self.handle_exception(e)
  File "/usr/local/lib/python3.9/dist-packages/flask/app.py", line 1463, in wsgi_app
    response = self.full_dispatch_request()
  File "/usr/local/lib/python3.9/dist-packages/flask/app.py", line 872, in full_dispatch_request
    rv = self.handle_user_exception(e)
  File "/usr/local/lib/python3.9/dist-packages/flask/app.py", line 870, in full_dispatch_request
    rv = self.dispatch_request()
  File "/usr/local/lib/python3.9/dist-packages/flask/app.py", line 855, in dispatch_request
    return self.ensure_sync(self.view_functions[rule.endpoint])(**view_args)  # type: ignore[no-any-return]
  File "/root/app.py", line 15, in home
    response = client.completions.create(
  File "/usr/local/lib/python3.9/dist-packages/openai/_utils/_utils.py", line 271, in wrapper
    return func(*args, **kwargs)
  File "/usr/local/lib/python3.9/dist-packages/openai/resources/completions.py", line 506, in create
    return self._post(
  File "/usr/local/lib/python3.9/dist-packages/openai/_base_client.py", line 1200, in post
    return cast(ResponseT, self.request(cast_to, opts, stream=stream, stream_cls=stream_cls))
  File "/usr/local/lib/python3.9/dist-packages/openai/_base_client.py", line 889, in request
    return self._request(
  File "/usr/local/lib/python3.9/dist-packages/openai/_base_client.py", line 980, in _request
    raise self._make_status_error_from_response(err.response) from None
openai.AuthenticationError: Error code: 401 - {'error': {'message': 'Incorrect API key provided: sua_chav*********aqui. You can find your API key at https://platform.openai.com/account/api-keys.', 'type': 'invalid_request_error', 'param': None, 'code': 'invalid_api_key'}}
192.168.0.181 - - [05/Feb/2024 21:56:42] "[36mGET /?__debugger__=yes&cmd=resource&f=style.css HTTP/1.1[0m" 304 -
192.168.0.181 - - [05/Feb/2024 21:56:42] "[36mGET /?__debugger__=yes&cmd=resource&f=debugger.js HTTP/1.1[0m" 304 -
192.168.0.181 - - [05/Feb/2024 21:56:42] "[36mGET /?__debugger__=yes&cmd=resource&f=console.png HTTP/1.1[0m" 304 -
 * Serving Flask app 'app'
 * Debug mode: on
Address already in use
Port 5000 is in use by another program. Either identify and stop that program, or start the server with a different port.
192.168.0.181 - - [05/Feb/2024 22:00:08] "[35m[1mPOST / HTTP/1.1[0m" 500 -
Traceback (most recent call last):
  File "/usr/local/lib/python3.9/dist-packages/flask/app.py", line 1488, in __call__
    return self.wsgi_app(environ, start_response)
  File "/usr/local/lib/python3.9/dist-packages/flask/app.py", line 1466, in wsgi_app
    response = self.handle_exception(e)
  File "/usr/local/lib/python3.9/dist-packages/flask/app.py", line 1463, in wsgi_app
    response = self.full_dispatch_request()
  File "/usr/local/lib/python3.9/dist-packages/flask/app.py", line 872, in full_dispatch_request
    rv = self.handle_user_exception(e)
  File "/usr/local/lib/python3.9/dist-packages/flask/app.py", line 870, in full_dispatch_request
    rv = self.dispatch_request()
  File "/usr/local/lib/python3.9/dist-packages/flask/app.py", line 855, in dispatch_request
    return self.ensure_sync(self.view_functions[rule.endpoint])(**view_args)  # type: ignore[no-any-return]
  File "/root/app.py", line 15, in home
    response = client.completions.create(
  File "/usr/local/lib/python3.9/dist-packages/openai/_utils/_utils.py", line 271, in wrapper
    return func(*args, **kwargs)
  File "/usr/local/lib/python3.9/dist-packages/openai/resources/completions.py", line 506, in create
    return self._post(
  File "/usr/local/lib/python3.9/dist-packages/openai/_base_client.py", line 1200, in post
    return cast(ResponseT, self.request(cast_to, opts, stream=stream, stream_cls=stream_cls))
  File "/usr/local/lib/python3.9/dist-packages/openai/_base_client.py", line 889, in request
    return self._request(
  File "/usr/local/lib/python3.9/dist-packages/openai/_base_client.py", line 980, in _request
    raise self._make_status_error_from_response(err.response) from None
openai.AuthenticationError: Error code: 401 - {'error': {'message': 'Incorrect API key provided: sua_chav*********aqui. You can find your API key at https://platform.openai.com/account/api-keys.', 'type': 'invalid_request_error', 'param': None, 'code': 'invalid_api_key'}}
192.168.0.181 - - [05/Feb/2024 22:00:08] "GET /?__debugger__=yes&cmd=resource&f=style.css HTTP/1.1" 200 -
192.168.0.181 - - [05/Feb/2024 22:00:08] "GET /?__debugger__=yes&cmd=resource&f=debugger.js HTTP/1.1" 200 -
192.168.0.181 - - [05/Feb/2024 22:00:08] "GET /?__debugger__=yes&cmd=resource&f=console.png HTTP/1.1" 200 -
192.168.0.181 - - [05/Feb/2024 22:00:08] "GET /?__debugger__=yes&cmd=resource&f=console.png HTTP/1.1" 200 -
192.168.0.181 - - [05/Feb/2024 22:00:13] "[35m[1mPOST / HTTP/1.1[0m" 500 -
Traceback (most recent call last):
  File "/usr/local/lib/python3.9/dist-packages/flask/app.py", line 1488, in __call__
    return self.wsgi_app(environ, start_response)
  File "/usr/local/lib/python3.9/dist-packages/flask/app.py", line 1466, in wsgi_app
    response = self.handle_exception(e)
  File "/usr/local/lib/python3.9/dist-packages/flask/app.py", line 1463, in wsgi_app
    response = self.full_dispatch_request()
  File "/usr/local/lib/python3.9/dist-packages/flask/app.py", line 872, in full_dispatch_request
    rv = self.handle_user_exception(e)
  File "/usr/local/lib/python3.9/dist-packages/flask/app.py", line 870, in full_dispatch_request
    rv = self.dispatch_request()
  File "/usr/local/lib/python3.9/dist-packages/flask/app.py", line 855, in dispatch_request
    return self.ensure_sync(self.view_functions[rule.endpoint])(**view_args)  # type: ignore[no-any-return]
  File "/root/app.py", line 15, in home
    response = client.completions.create(
  File "/usr/local/lib/python3.9/dist-packages/openai/_utils/_utils.py", line 271, in wrapper
    return func(*args, **kwargs)
  File "/usr/local/lib/python3.9/dist-packages/openai/resources/completions.py", line 506, in create
    return self._post(
  File "/usr/local/lib/python3.9/dist-packages/openai/_base_client.py", line 1200, in post
    return cast(ResponseT, self.request(cast_to, opts, stream=stream, stream_cls=stream_cls))
  File "/usr/local/lib/python3.9/dist-packages/openai/_base_client.py", line 889, in request
    return self._request(
  File "/usr/local/lib/python3.9/dist-packages/openai/_base_client.py", line 980, in _request
    raise self._make_status_error_from_response(err.response) from None
openai.AuthenticationError: Error code: 401 - {'error': {'message': 'Incorrect API key provided: sua_chav*********aqui. You can find your API key at https://platform.openai.com/account/api-keys.', 'type': 'invalid_request_error', 'param': None, 'code': 'invalid_api_key'}}
192.168.0.181 - - [05/Feb/2024 22:00:14] "[36mGET /?__debugger__=yes&cmd=resource&f=style.css HTTP/1.1[0m" 304 -
192.168.0.181 - - [05/Feb/2024 22:00:14] "[36mGET /?__debugger__=yes&cmd=resource&f=debugger.js HTTP/1.1[0m" 304 -
192.168.0.181 - - [05/Feb/2024 22:00:14] "[36mGET /?__debugger__=yes&cmd=resource&f=console.png HTTP/1.1[0m" 304 -
 * Detected change in '/root/app.py', reloading
 * Restarting with stat
 * Debugger is active!
 * Debugger PIN: 480-715-215
 * Detected change in '/root/app.py', reloading
 * Restarting with stat
 * Debugger is active!
 * Debugger PIN: 480-715-215
 * Serving Flask app 'app'
 * Debug mode: on
Address already in use
Port 5000 is in use by another program. Either identify and stop that program, or start the server with a different port.
192.168.0.181 - - [05/Feb/2024 22:05:56] "GET / HTTP/1.1" 200 -
192.168.0.181 - - [05/Feb/2024 22:06:00] "[35m[1mPOST / HTTP/1.1[0m" 500 -
Traceback (most recent call last):
  File "/usr/local/lib/python3.9/dist-packages/flask/app.py", line 1488, in __call__
    return self.wsgi_app(environ, start_response)
  File "/usr/local/lib/python3.9/dist-packages/flask/app.py", line 1466, in wsgi_app
    response = self.handle_exception(e)
  File "/usr/local/lib/python3.9/dist-packages/flask/app.py", line 1463, in wsgi_app
    response = self.full_dispatch_request()
  File "/usr/local/lib/python3.9/dist-packages/flask/app.py", line 872, in full_dispatch_request
    rv = self.handle_user_exception(e)
  File "/usr/local/lib/python3.9/dist-packages/flask/app.py", line 870, in full_dispatch_request
    rv = self.dispatch_request()
  File "/usr/local/lib/python3.9/dist-packages/flask/app.py", line 855, in dispatch_request
    return self.ensure_sync(self.view_functions[rule.endpoint])(**view_args)  # type: ignore[no-any-return]
  File "/root/app.py", line 15, in home
    response = client.completions.create(
  File "/usr/local/lib/python3.9/dist-packages/openai/_utils/_utils.py", line 271, in wrapper
    return func(*args, **kwargs)
  File "/usr/local/lib/python3.9/dist-packages/openai/resources/completions.py", line 506, in create
    return self._post(
  File "/usr/local/lib/python3.9/dist-packages/openai/_base_client.py", line 1200, in post
    return cast(ResponseT, self.request(cast_to, opts, stream=stream, stream_cls=stream_cls))
  File "/usr/local/lib/python3.9/dist-packages/openai/_base_client.py", line 889, in request
    return self._request(
  File "/usr/local/lib/python3.9/dist-packages/openai/_base_client.py", line 980, in _request
    raise self._make_status_error_from_response(err.response) from None
openai.AuthenticationError: Error code: 401 - {'error': {'message': 'Incorrect API key provided: sua_chav*********aqui. You can find your API key at https://platform.openai.com/account/api-keys.', 'type': 'invalid_request_error', 'param': None, 'code': 'invalid_api_key'}}
192.168.0.181 - - [05/Feb/2024 22:06:00] "[36mGET /?__debugger__=yes&cmd=resource&f=style.css HTTP/1.1[0m" 304 -
192.168.0.181 - - [05/Feb/2024 22:06:00] "[36mGET /?__debugger__=yes&cmd=resource&f=debugger.js HTTP/1.1[0m" 304 -
192.168.0.181 - - [05/Feb/2024 22:06:00] "[36mGET /?__debugger__=yes&cmd=resource&f=console.png HTTP/1.1[0m" 304 -
 * Serving Flask app 'app'
 * Debug mode: on
[31m[1mWARNING: This is a development server. Do not use it in a production deployment. Use a production WSGI server instead.[0m
 * Running on all addresses (0.0.0.0)
 * Running on http://127.0.0.1:5000
 * Running on http://192.168.0.28:5000
[33mPress CTRL+C to quit[0m
 * Restarting with stat
 * Debugger is active!
 * Debugger PIN: 480-715-215
192.168.0.181 - - [05/Feb/2024 22:09:12] "GET / HTTP/1.1" 200 -
192.168.0.181 - - [05/Feb/2024 22:09:16] "[35m[1mPOST / HTTP/1.1[0m" 500 -
Traceback (most recent call last):
  File "/usr/local/lib/python3.9/dist-packages/flask/app.py", line 1488, in __call__
    return self.wsgi_app(environ, start_response)
  File "/usr/local/lib/python3.9/dist-packages/flask/app.py", line 1466, in wsgi_app
    response = self.handle_exception(e)
  File "/usr/local/lib/python3.9/dist-packages/flask/app.py", line 1463, in wsgi_app
    response = self.full_dispatch_request()
  File "/usr/local/lib/python3.9/dist-packages/flask/app.py", line 872, in full_dispatch_request
    rv = self.handle_user_exception(e)
  File "/usr/local/lib/python3.9/dist-packages/flask/app.py", line 870, in full_dispatch_request
    rv = self.dispatch_request()
  File "/usr/local/lib/python3.9/dist-packages/flask/app.py", line 855, in dispatch_request
    return self.ensure_sync(self.view_functions[rule.endpoint])(**view_args)  # type: ignore[no-any-return]
  File "/root/app.py", line 15, in home
    response = client.completions.create(
  File "/usr/local/lib/python3.9/dist-packages/openai/_utils/_utils.py", line 271, in wrapper
    return func(*args, **kwargs)
  File "/usr/local/lib/python3.9/dist-packages/openai/resources/completions.py", line 506, in create
    return self._post(
  File "/usr/local/lib/python3.9/dist-packages/openai/_base_client.py", line 1200, in post
    return cast(ResponseT, self.request(cast_to, opts, stream=stream, stream_cls=stream_cls))
  File "/usr/local/lib/python3.9/dist-packages/openai/_base_client.py", line 889, in request
    return self._request(
  File "/usr/local/lib/python3.9/dist-packages/openai/_base_client.py", line 980, in _request
    raise self._make_status_error_from_response(err.response) from None
openai.NotFoundError: Error code: 404 - {'error': {'message': 'This is a chat model and not supported in the v1/completions endpoint. Did you mean to use v1/chat/completions?', 'type': 'invalid_request_error', 'param': 'model', 'code': None}}
192.168.0.181 - - [05/Feb/2024 22:09:16] "[36mGET /?__debugger__=yes&cmd=resource&f=style.css HTTP/1.1[0m" 304 -
192.168.0.181 - - [05/Feb/2024 22:09:16] "[36mGET /?__debugger__=yes&cmd=resource&f=debugger.js HTTP/1.1[0m" 304 -
192.168.0.181 - - [05/Feb/2024 22:09:16] "[36mGET /?__debugger__=yes&cmd=resource&f=console.png HTTP/1.1[0m" 304 -
192.168.0.181 - - [05/Feb/2024 22:12:45] "GET / HTTP/1.1" 200 -
192.168.0.181 - - [05/Feb/2024 22:17:21] "[35m[1mPOST / HTTP/1.1[0m" 500 -
Traceback (most recent call last):
  File "/usr/local/lib/python3.9/dist-packages/flask/app.py", line 1488, in __call__
    return self.wsgi_app(environ, start_response)
  File "/usr/local/lib/python3.9/dist-packages/flask/app.py", line 1466, in wsgi_app
    response = self.handle_exception(e)
  File "/usr/local/lib/python3.9/dist-packages/flask/app.py", line 1463, in wsgi_app
    response = self.full_dispatch_request()
  File "/usr/local/lib/python3.9/dist-packages/flask/app.py", line 872, in full_dispatch_request
    rv = self.handle_user_exception(e)
  File "/usr/local/lib/python3.9/dist-packages/flask/app.py", line 870, in full_dispatch_request
    rv = self.dispatch_request()
  File "/usr/local/lib/python3.9/dist-packages/flask/app.py", line 855, in dispatch_request
    return self.ensure_sync(self.view_functions[rule.endpoint])(**view_args)  # type: ignore[no-any-return]
  File "/root/app.py", line 15, in home
    response = client.completions.create(
  File "/usr/local/lib/python3.9/dist-packages/openai/_utils/_utils.py", line 271, in wrapper
    return func(*args, **kwargs)
  File "/usr/local/lib/python3.9/dist-packages/openai/resources/completions.py", line 506, in create
    return self._post(
  File "/usr/local/lib/python3.9/dist-packages/openai/_base_client.py", line 1200, in post
    return cast(ResponseT, self.request(cast_to, opts, stream=stream, stream_cls=stream_cls))
  File "/usr/local/lib/python3.9/dist-packages/openai/_base_client.py", line 889, in request
    return self._request(
  File "/usr/local/lib/python3.9/dist-packages/openai/_base_client.py", line 980, in _request
    raise self._make_status_error_from_response(err.response) from None
openai.NotFoundError: Error code: 404 - {'error': {'message': 'This is a chat model and not supported in the v1/completions endpoint. Did you mean to use v1/chat/completions?', 'type': 'invalid_request_error', 'param': 'model', 'code': None}}
192.168.0.181 - - [05/Feb/2024 22:17:21] "[36mGET /?__debugger__=yes&cmd=resource&f=style.css HTTP/1.1[0m" 304 -
192.168.0.181 - - [05/Feb/2024 22:17:21] "[36mGET /?__debugger__=yes&cmd=resource&f=debugger.js HTTP/1.1[0m" 304 -
192.168.0.181 - - [05/Feb/2024 22:17:21] "[36mGET /?__debugger__=yes&cmd=resource&f=console.png HTTP/1.1[0m" 304 -
 * Serving Flask app 'app'
 * Debug mode: on
[31m[1mWARNING: This is a development server. Do not use it in a production deployment. Use a production WSGI server instead.[0m
 * Running on all addresses (0.0.0.0)
 * Running on http://127.0.0.1:5000
 * Running on http://192.168.0.28:5000
[33mPress CTRL+C to quit[0m
 * Restarting with stat
 * Debugger is active!
 * Debugger PIN: 480-715-215
192.168.0.181 - - [05/Feb/2024 22:41:04] "GET / HTTP/1.1" 200 -
192.168.0.181 - - [05/Feb/2024 22:41:07] "[35m[1mPOST / HTTP/1.1[0m" 500 -
Traceback (most recent call last):
  File "/usr/local/lib/python3.9/dist-packages/flask/app.py", line 1488, in __call__
    return self.wsgi_app(environ, start_response)
  File "/usr/local/lib/python3.9/dist-packages/flask/app.py", line 1466, in wsgi_app
    response = self.handle_exception(e)
  File "/usr/local/lib/python3.9/dist-packages/flask/app.py", line 1463, in wsgi_app
    response = self.full_dispatch_request()
  File "/usr/local/lib/python3.9/dist-packages/flask/app.py", line 872, in full_dispatch_request
    rv = self.handle_user_exception(e)
  File "/usr/local/lib/python3.9/dist-packages/flask/app.py", line 870, in full_dispatch_request
    rv = self.dispatch_request()
  File "/usr/local/lib/python3.9/dist-packages/flask/app.py", line 855, in dispatch_request
    return self.ensure_sync(self.view_functions[rule.endpoint])(**view_args)  # type: ignore[no-any-return]
  File "/root/app.py", line 15, in home
    response = openai.ChatCompletions.create(
NameError: name 'openai' is not defined
192.168.0.181 - - [05/Feb/2024 22:41:07] "[36mGET /?__debugger__=yes&cmd=resource&f=style.css HTTP/1.1[0m" 304 -
192.168.0.181 - - [05/Feb/2024 22:41:07] "[36mGET /?__debugger__=yes&cmd=resource&f=debugger.js HTTP/1.1[0m" 304 -
192.168.0.181 - - [05/Feb/2024 22:41:07] "[36mGET /?__debugger__=yes&cmd=resource&f=console.png HTTP/1.1[0m" 304 -
 * Detected change in '/root/app.py', reloading
 * Restarting with stat
 * Debugger is active!
 * Debugger PIN: 480-715-215
 * Serving Flask app 'app'
 * Debug mode: on
Address already in use
Port 5000 is in use by another program. Either identify and stop that program, or start the server with a different port.
192.168.0.181 - - [05/Feb/2024 22:45:47] "GET / HTTP/1.1" 200 -
192.168.0.181 - - [05/Feb/2024 22:45:51] "[35m[1mPOST / HTTP/1.1[0m" 500 -
Traceback (most recent call last):
  File "/usr/local/lib/python3.9/dist-packages/flask/app.py", line 1488, in __call__
    return self.wsgi_app(environ, start_response)
  File "/usr/local/lib/python3.9/dist-packages/flask/app.py", line 1466, in wsgi_app
    response = self.handle_exception(e)
  File "/usr/local/lib/python3.9/dist-packages/flask/app.py", line 1463, in wsgi_app
    response = self.full_dispatch_request()
  File "/usr/local/lib/python3.9/dist-packages/flask/app.py", line 872, in full_dispatch_request
    rv = self.handle_user_exception(e)
  File "/usr/local/lib/python3.9/dist-packages/flask/app.py", line 870, in full_dispatch_request
    rv = self.dispatch_request()
  File "/usr/local/lib/python3.9/dist-packages/flask/app.py", line 855, in dispatch_request
    return self.ensure_sync(self.view_functions[rule.endpoint])(**view_args)  # type: ignore[no-any-return]
  File "/root/app.py", line 15, in home
    response = client.chat.completions.create(
  File "/usr/local/lib/python3.9/dist-packages/openai/_utils/_utils.py", line 270, in wrapper
    raise TypeError(msg)
TypeError: Missing required arguments; Expected either ('messages' and 'model') or ('messages', 'model' and 'stream') arguments to be given
192.168.0.181 - - [05/Feb/2024 22:45:51] "[36mGET /?__debugger__=yes&cmd=resource&f=style.css HTTP/1.1[0m" 304 -
192.168.0.181 - - [05/Feb/2024 22:45:51] "[36mGET /?__debugger__=yes&cmd=resource&f=debugger.js HTTP/1.1[0m" 304 -
192.168.0.181 - - [05/Feb/2024 22:45:51] "[36mGET /?__debugger__=yes&cmd=resource&f=console.png HTTP/1.1[0m" 304 -
 * Detected change in '/root/app.py', reloading
 * Restarting with stat
 * Debugger is active!
 * Debugger PIN: 480-715-215
 * Serving Flask app 'app'
 * Debug mode: on
Address already in use
Port 5000 is in use by another program. Either identify and stop that program, or start the server with a different port.
192.168.0.181 - - [05/Feb/2024 22:48:45] "GET / HTTP/1.1" 200 -
192.168.0.181 - - [05/Feb/2024 22:48:51] "POST / HTTP/1.1" 200 -
192.168.0.181 - - [05/Feb/2024 22:49:57] "GET / HTTP/1.1" 200 -
 * Detected change in '/root/app.py', reloading
 * Restarting with stat
 * Debugger is active!
 * Debugger PIN: 480-715-215
 * Serving Flask app 'app'
 * Debug mode: on
Address already in use
Port 5000 is in use by another program. Either identify and stop that program, or start the server with a different port.
192.168.0.181 - - [05/Feb/2024 22:51:19] "GET / HTTP/1.1" 200 -
192.168.0.181 - - [05/Feb/2024 22:51:22] "GET / HTTP/1.1" 200 -
192.168.0.181 - - [05/Feb/2024 22:51:27] "POST / HTTP/1.1" 200 -
192.168.0.181 - - [05/Feb/2024 22:51:36] "GET / HTTP/1.1" 200 -
192.168.0.181 - - [05/Feb/2024 22:52:16] "POST / HTTP/1.1" 200 -
 * Detected change in '/root/app.py', reloading
 * Restarting with stat
 * Debugger is active!
 * Debugger PIN: 480-715-215
192.168.0.181 - - [05/Feb/2024 22:54:23] "GET / HTTP/1.1" 200 -
192.168.0.181 - - [05/Feb/2024 22:54:47] "[35m[1mPOST / HTTP/1.1[0m" 500 -
Traceback (most recent call last):
  File "/usr/local/lib/python3.9/dist-packages/flask/app.py", line 1488, in __call__
    return self.wsgi_app(environ, start_response)
  File "/usr/local/lib/python3.9/dist-packages/flask/app.py", line 1466, in wsgi_app
    response = self.handle_exception(e)
  File "/usr/local/lib/python3.9/dist-packages/flask/app.py", line 1463, in wsgi_app
    response = self.full_dispatch_request()
  File "/usr/local/lib/python3.9/dist-packages/flask/app.py", line 872, in full_dispatch_request
    rv = self.handle_user_exception(e)
  File "/usr/local/lib/python3.9/dist-packages/flask/app.py", line 870, in full_dispatch_request
    rv = self.dispatch_request()
  File "/usr/local/lib/python3.9/dist-packages/flask/app.py", line 855, in dispatch_request
    return self.ensure_sync(self.view_functions[rule.endpoint])(**view_args)  # type: ignore[no-any-return]
  File "/root/app.py", line 15, in home
    response = client.chat.completions.create(
  File "/usr/local/lib/python3.9/dist-packages/openai/_utils/_utils.py", line 271, in wrapper
    return func(*args, **kwargs)
  File "/usr/local/lib/python3.9/dist-packages/openai/resources/chat/completions.py", line 659, in create
    return self._post(
  File "/usr/local/lib/python3.9/dist-packages/openai/_base_client.py", line 1200, in post
    return cast(ResponseT, self.request(cast_to, opts, stream=stream, stream_cls=stream_cls))
  File "/usr/local/lib/python3.9/dist-packages/openai/_base_client.py", line 889, in request
    return self._request(
  File "/usr/local/lib/python3.9/dist-packages/openai/_base_client.py", line 980, in _request
    raise self._make_status_error_from_response(err.response) from None
openai.BadRequestError: Error code: 400 - {'error': {'message': "This model's maximum context length is 4097 tokens. However, you requested 5026 tokens (26 in the messages, 5000 in the completion). Please reduce the length of the messages or completion.", 'type': 'invalid_request_error', 'param': 'messages', 'code': 'context_length_exceeded'}}
192.168.0.181 - - [05/Feb/2024 22:54:47] "[36mGET /?__debugger__=yes&cmd=resource&f=style.css HTTP/1.1[0m" 304 -
192.168.0.181 - - [05/Feb/2024 22:54:48] "[36mGET /?__debugger__=yes&cmd=resource&f=debugger.js HTTP/1.1[0m" 304 -
192.168.0.181 - - [05/Feb/2024 22:54:48] "[36mGET /?__debugger__=yes&cmd=resource&f=console.png HTTP/1.1[0m" 304 -
192.168.0.181 - - [05/Feb/2024 22:54:48] "[36mGET /?__debugger__=yes&cmd=resource&f=console.png HTTP/1.1[0m" 304 -
 * Detected change in '/root/app.py', reloading
 * Restarting with stat
 * Debugger is active!
 * Debugger PIN: 480-715-215
192.168.0.181 - - [05/Feb/2024 22:55:20] "GET / HTTP/1.1" 200 -
192.168.0.181 - - [05/Feb/2024 22:55:39] "POST / HTTP/1.1" 200 -
 * Detected change in '/root/app.py', reloading
 * Restarting with stat
 * Debugger is active!
 * Debugger PIN: 480-715-215
192.168.0.181 - - [05/Feb/2024 22:56:41] "GET / HTTP/1.1" 200 -
192.168.0.181 - - [05/Feb/2024 22:57:01] "POST / HTTP/1.1" 200 -
192.168.0.181 - - [06/Feb/2024 00:00:20] "GET / HTTP/1.1" 200 -
192.168.0.181 - - [06/Feb/2024 00:00:21] "[33mGET /favicon.ico HTTP/1.1[0m" 404 -
 * Detected change in '/root/app.py', reloading
 * Restarting with stat
 * Debugger is active!
 * Debugger PIN: 480-715-215
 * Detected change in '/root/app.py', reloading
 * Restarting with stat
 * Debugger is active!
 * Debugger PIN: 480-715-215
192.168.0.181 - - [06/Feb/2024 00:45:32] "[35m[1mGET / HTTP/1.1[0m" 500 -
Traceback (most recent call last):
  File "/usr/local/lib/python3.9/dist-packages/flask/app.py", line 1488, in __call__
    return self.wsgi_app(environ, start_response)
  File "/usr/local/lib/python3.9/dist-packages/flask/app.py", line 1466, in wsgi_app
    response = self.handle_exception(e)
  File "/usr/local/lib/python3.9/dist-packages/flask/app.py", line 1463, in wsgi_app
    response = self.full_dispatch_request()
  File "/usr/local/lib/python3.9/dist-packages/flask/app.py", line 872, in full_dispatch_request
    rv = self.handle_user_exception(e)
  File "/usr/local/lib/python3.9/dist-packages/flask/app.py", line 870, in full_dispatch_request
    rv = self.dispatch_request()
  File "/usr/local/lib/python3.9/dist-packages/flask/app.py", line 855, in dispatch_request
    return self.ensure_sync(self.view_functions[rule.endpoint])(**view_args)  # type: ignore[no-any-return]
  File "/root/app.py", line 23, in home
    return render_template("template.html")
  File "/usr/local/lib/python3.9/dist-packages/flask/templating.py", line 149, in render_template
    template = app.jinja_env.get_or_select_template(template_name_or_list)
  File "/usr/local/lib/python3.9/dist-packages/jinja2/environment.py", line 1081, in get_or_select_template
    return self.get_template(template_name_or_list, parent, globals)
  File "/usr/local/lib/python3.9/dist-packages/jinja2/environment.py", line 1010, in get_template
    return self._load_template(name, globals)
  File "/usr/local/lib/python3.9/dist-packages/jinja2/environment.py", line 969, in _load_template
    template = self.loader.load(self, name, self.make_globals(globals))
  File "/usr/local/lib/python3.9/dist-packages/jinja2/loaders.py", line 125, in load
    source, filename, uptodate = self.get_source(environment, name)
  File "/usr/local/lib/python3.9/dist-packages/flask/templating.py", line 65, in get_source
    return self._get_source_fast(environment, template)
  File "/usr/local/lib/python3.9/dist-packages/flask/templating.py", line 99, in _get_source_fast
    raise TemplateNotFound(template)
jinja2.exceptions.TemplateNotFound: template.html
192.168.0.181 - - [06/Feb/2024 00:45:32] "GET /?__debugger__=yes&cmd=resource&f=style.css HTTP/1.1" 200 -
192.168.0.181 - - [06/Feb/2024 00:45:32] "GET /?__debugger__=yes&cmd=resource&f=debugger.js HTTP/1.1" 200 -
192.168.0.181 - - [06/Feb/2024 00:45:32] "GET /?__debugger__=yes&cmd=resource&f=console.png HTTP/1.1" 200 -
192.168.0.181 - - [06/Feb/2024 00:45:33] "GET /?__debugger__=yes&cmd=resource&f=console.png HTTP/1.1" 200 -
192.168.0.181 - - [06/Feb/2024 00:53:17] "[35m[1mGET / HTTP/1.1[0m" 500 -
Traceback (most recent call last):
  File "/usr/local/lib/python3.9/dist-packages/flask/app.py", line 1488, in __call__
    return self.wsgi_app(environ, start_response)
  File "/usr/local/lib/python3.9/dist-packages/flask/app.py", line 1466, in wsgi_app
    response = self.handle_exception(e)
  File "/usr/local/lib/python3.9/dist-packages/flask/app.py", line 1463, in wsgi_app
    response = self.full_dispatch_request()
  File "/usr/local/lib/python3.9/dist-packages/flask/app.py", line 872, in full_dispatch_request
    rv = self.handle_user_exception(e)
  File "/usr/local/lib/python3.9/dist-packages/flask/app.py", line 870, in full_dispatch_request
    rv = self.dispatch_request()
  File "/usr/local/lib/python3.9/dist-packages/flask/app.py", line 855, in dispatch_request
    return self.ensure_sync(self.view_functions[rule.endpoint])(**view_args)  # type: ignore[no-any-return]
  File "/root/app.py", line 23, in home
    return render_template("template.html")
  File "/usr/local/lib/python3.9/dist-packages/flask/templating.py", line 149, in render_template
    template = app.jinja_env.get_or_select_template(template_name_or_list)
  File "/usr/local/lib/python3.9/dist-packages/jinja2/environment.py", line 1081, in get_or_select_template
    return self.get_template(template_name_or_list, parent, globals)
  File "/usr/local/lib/python3.9/dist-packages/jinja2/environment.py", line 1010, in get_template
    return self._load_template(name, globals)
  File "/usr/local/lib/python3.9/dist-packages/jinja2/environment.py", line 969, in _load_template
    template = self.loader.load(self, name, self.make_globals(globals))
  File "/usr/local/lib/python3.9/dist-packages/jinja2/loaders.py", line 125, in load
    source, filename, uptodate = self.get_source(environment, name)
  File "/usr/local/lib/python3.9/dist-packages/flask/templating.py", line 65, in get_source
    return self._get_source_fast(environment, template)
  File "/usr/local/lib/python3.9/dist-packages/flask/templating.py", line 99, in _get_source_fast
    raise TemplateNotFound(template)
jinja2.exceptions.TemplateNotFound: template.html
192.168.0.181 - - [06/Feb/2024 00:53:17] "[36mGET /?__debugger__=yes&cmd=resource&f=style.css HTTP/1.1[0m" 304 -
192.168.0.181 - - [06/Feb/2024 00:53:17] "[36mGET /?__debugger__=yes&cmd=resource&f=debugger.js HTTP/1.1[0m" 304 -
192.168.0.181 - - [06/Feb/2024 00:53:18] "[36mGET /?__debugger__=yes&cmd=resource&f=console.png HTTP/1.1[0m" 304 -
192.168.0.181 - - [06/Feb/2024 00:53:18] "[36mGET /?__debugger__=yes&cmd=resource&f=console.png HTTP/1.1[0m" 304 -
192.168.0.181 - - [06/Feb/2024 01:02:14] "GET / HTTP/1.1" 200 -
192.168.0.181 - - [06/Feb/2024 01:02:28] "GET / HTTP/1.1" 200 -
192.168.0.181 - - [06/Feb/2024 01:02:29] "GET / HTTP/1.1" 200 -
192.168.0.181 - - [06/Feb/2024 01:02:30] "GET / HTTP/1.1" 200 -
192.168.0.181 - - [06/Feb/2024 01:09:57] "GET / HTTP/1.1" 200 -
192.168.0.181 - - [06/Feb/2024 01:09:57] "[33mGET /favicon.ico HTTP/1.1[0m" 404 -
192.168.0.181 - - [06/Feb/2024 01:09:58] "GET / HTTP/1.1" 200 -
192.168.0.181 - - [06/Feb/2024 01:11:20] "GET / HTTP/1.1" 200 -
192.168.0.181 - - [06/Feb/2024 01:11:20] "[33mGET /favicon.ico HTTP/1.1[0m" 404 -
192.168.0.181 - - [06/Feb/2024 01:11:21] "GET / HTTP/1.1" 200 -
192.168.0.181 - - [06/Feb/2024 01:20:06] "GET / HTTP/1.1" 200 -
 * Detected change in '/root/app.py', reloading
 * Restarting with stat
Traceback (most recent call last):
  File "/root/app.py", line 2, in <module>
    from flask_session import Session
ModuleNotFoundError: No module named 'flask_session'
Traceback (most recent call last):
  File "/root/app.py", line 2, in <module>
    from flask_session import Session
ModuleNotFoundError: No module named 'flask_session'
 * Serving Flask app 'app'
 * Debug mode: on
[31m[1mWARNING: This is a development server. Do not use it in a production deployment. Use a production WSGI server instead.[0m
 * Running on all addresses (0.0.0.0)
 * Running on http://127.0.0.1:5000
 * Running on http://192.168.0.28:5000
[33mPress CTRL+C to quit[0m
 * Restarting with stat
 * Debugger is active!
 * Debugger PIN: 729-843-404
192.168.0.181 - - [06/Feb/2024 02:04:00] "GET / HTTP/1.1" 200 -
192.168.0.181 - - [06/Feb/2024 02:04:21] "POST / HTTP/1.1" 200 -
192.168.0.181 - - [06/Feb/2024 02:04:34] "POST / HTTP/1.1" 200 -
 * Detected change in '/root/app.py', reloading
 * Restarting with stat
 * Debugger is active!
 * Debugger PIN: 729-843-404
192.168.0.181 - - [06/Feb/2024 02:11:43] "GET / HTTP/1.1" 200 -
192.168.0.181 - - [06/Feb/2024 02:11:48] "GET / HTTP/1.1" 200 -
192.168.0.181 - - [06/Feb/2024 02:11:49] "GET / HTTP/1.1" 200 -
192.168.0.181 - - [06/Feb/2024 02:11:50] "GET / HTTP/1.1" 200 -
192.168.0.181 - - [06/Feb/2024 02:11:50] "GET / HTTP/1.1" 200 -
192.168.0.181 - - [06/Feb/2024 02:11:52] "GET / HTTP/1.1" 200 -
 * Serving Flask app 'app'
 * Debug mode: on
Address already in use
Port 5000 is in use by another program. Either identify and stop that program, or start the server with a different port.
192.168.0.181 - - [06/Feb/2024 02:12:13] "GET / HTTP/1.1" 200 -
192.168.0.181 - - [06/Feb/2024 02:12:20] "[35m[1mPOST / HTTP/1.1[0m" 500 -
Traceback (most recent call last):
  File "/usr/local/lib/python3.9/dist-packages/flask/app.py", line 1488, in __call__
    return self.wsgi_app(environ, start_response)
  File "/usr/local/lib/python3.9/dist-packages/flask/app.py", line 1466, in wsgi_app
    response = self.handle_exception(e)
  File "/usr/local/lib/python3.9/dist-packages/flask/app.py", line 1463, in wsgi_app
    response = self.full_dispatch_request()
  File "/usr/local/lib/python3.9/dist-packages/flask/app.py", line 872, in full_dispatch_request
    rv = self.handle_user_exception(e)
  File "/usr/local/lib/python3.9/dist-packages/flask/app.py", line 870, in full_dispatch_request
    rv = self.dispatch_request()
  File "/usr/local/lib/python3.9/dist-packages/flask/app.py", line 855, in dispatch_request
    return self.ensure_sync(self.view_functions[rule.endpoint])(**view_args)  # type: ignore[no-any-return]
  File "/root/app.py", line 22, in home
    response = openai.ChatCompletion.create(
  File "/usr/local/lib/python3.9/dist-packages/openai/lib/_old_api.py", line 39, in __call__
    raise APIRemovedInV1(symbol=self._symbol)
openai.lib._old_api.APIRemovedInV1: 

You tried to access openai.ChatCompletion, but this is no longer supported in openai>=1.0.0 - see the README at https://github.com/openai/openai-python for the API.

You can run `openai migrate` to automatically upgrade your codebase to use the 1.0.0 interface. 

Alternatively, you can pin your installation to the old version, e.g. `pip install openai==0.28`

A detailed migration guide is available here: https://github.com/openai/openai-python/discussions/742

192.168.0.181 - - [06/Feb/2024 02:12:20] "[36mGET /?__debugger__=yes&cmd=resource&f=style.css HTTP/1.1[0m" 304 -
192.168.0.181 - - [06/Feb/2024 02:12:20] "[36mGET /?__debugger__=yes&cmd=resource&f=debugger.js HTTP/1.1[0m" 304 -
192.168.0.181 - - [06/Feb/2024 02:12:20] "[36mGET /?__debugger__=yes&cmd=resource&f=console.png HTTP/1.1[0m" 304 -
192.168.0.181 - - [06/Feb/2024 02:12:21] "[36mGET /?__debugger__=yes&cmd=resource&f=console.png HTTP/1.1[0m" 304 -
 * Detected change in '/root/app.py', reloading
 * Restarting with stat
Traceback (most recent call last):
  File "/root/app.py", line 5, in <module>
    client = OpenAI(api_key=os.getenv("OPENAI_API_KEY"))
NameError: name 'os' is not defined
Traceback (most recent call last):
  File "/root/app.py", line 5, in <module>
    client = OpenAI(api_key=os.getenv("OPENAI_API_KEY"))
NameError: name 'os' is not defined
 * Serving Flask app 'app'
 * Debug mode: on
[31m[1mWARNING: This is a development server. Do not use it in a production deployment. Use a production WSGI server instead.[0m
 * Running on all addresses (0.0.0.0)
 * Running on http://127.0.0.1:5000
 * Running on http://192.168.0.28:5000
[33mPress CTRL+C to quit[0m
 * Restarting with stat
 * Debugger is active!
 * Debugger PIN: 729-843-404
192.168.0.181 - - [06/Feb/2024 02:16:16] "GET / HTTP/1.1" 200 -
192.168.0.181 - - [06/Feb/2024 02:16:25] "[35m[1mPOST / HTTP/1.1[0m" 500 -
Traceback (most recent call last):
  File "/usr/local/lib/python3.9/dist-packages/flask/app.py", line 1488, in __call__
    return self.wsgi_app(environ, start_response)
  File "/usr/local/lib/python3.9/dist-packages/flask/app.py", line 1466, in wsgi_app
    response = self.handle_exception(e)
  File "/usr/local/lib/python3.9/dist-packages/flask/app.py", line 1463, in wsgi_app
    response = self.full_dispatch_request()
  File "/usr/local/lib/python3.9/dist-packages/flask/app.py", line 872, in full_dispatch_request
    rv = self.handle_user_exception(e)
  File "/usr/local/lib/python3.9/dist-packages/flask/app.py", line 870, in full_dispatch_request
    rv = self.dispatch_request()
  File "/usr/local/lib/python3.9/dist-packages/flask/app.py", line 855, in dispatch_request
    return self.ensure_sync(self.view_functions[rule.endpoint])(**view_args)  # type: ignore[no-any-return]
  File "/root/app.py", line 24, in home
    response = client.chat.completions.create(model="gpt-3.5-turbo",
  File "/usr/local/lib/python3.9/dist-packages/openai/_utils/_utils.py", line 271, in wrapper
    return func(*args, **kwargs)
  File "/usr/local/lib/python3.9/dist-packages/openai/resources/chat/completions.py", line 659, in create
    return self._post(
  File "/usr/local/lib/python3.9/dist-packages/openai/_base_client.py", line 1200, in post
    return cast(ResponseT, self.request(cast_to, opts, stream=stream, stream_cls=stream_cls))
  File "/usr/local/lib/python3.9/dist-packages/openai/_base_client.py", line 889, in request
    return self._request(
  File "/usr/local/lib/python3.9/dist-packages/openai/_base_client.py", line 980, in _request
    raise self._make_status_error_from_response(err.response) from None
openai.AuthenticationError: Error code: 401 - {'error': {'message': 'Incorrect API key provided: sua_chav*********aqui. You can find your API key at https://platform.openai.com/account/api-keys.', 'type': 'invalid_request_error', 'param': None, 'code': 'invalid_api_key'}}
192.168.0.181 - - [06/Feb/2024 02:16:25] "[36mGET /?__debugger__=yes&cmd=resource&f=debugger.js HTTP/1.1[0m" 304 -
192.168.0.181 - - [06/Feb/2024 02:16:25] "[36mGET /?__debugger__=yes&cmd=resource&f=style.css HTTP/1.1[0m" 304 -
192.168.0.181 - - [06/Feb/2024 02:16:25] "[36mGET /?__debugger__=yes&cmd=resource&f=console.png HTTP/1.1[0m" 304 -
192.168.0.181 - - [06/Feb/2024 02:16:25] "[36mGET /?__debugger__=yes&cmd=resource&f=console.png HTTP/1.1[0m" 304 -
 * Serving Flask app 'app'
 * Debug mode: on
Address already in use
Port 5000 is in use by another program. Either identify and stop that program, or start the server with a different port.
192.168.0.181 - - [06/Feb/2024 02:17:33] "GET / HTTP/1.1" 200 -
192.168.0.181 - - [06/Feb/2024 02:17:41] "[35m[1mPOST / HTTP/1.1[0m" 500 -
Traceback (most recent call last):
  File "/usr/local/lib/python3.9/dist-packages/flask/app.py", line 1488, in __call__
    return self.wsgi_app(environ, start_response)
  File "/usr/local/lib/python3.9/dist-packages/flask/app.py", line 1466, in wsgi_app
    response = self.handle_exception(e)
  File "/usr/local/lib/python3.9/dist-packages/flask/app.py", line 1463, in wsgi_app
    response = self.full_dispatch_request()
  File "/usr/local/lib/python3.9/dist-packages/flask/app.py", line 872, in full_dispatch_request
    rv = self.handle_user_exception(e)
  File "/usr/local/lib/python3.9/dist-packages/flask/app.py", line 870, in full_dispatch_request
    rv = self.dispatch_request()
  File "/usr/local/lib/python3.9/dist-packages/flask/app.py", line 855, in dispatch_request
    return self.ensure_sync(self.view_functions[rule.endpoint])(**view_args)  # type: ignore[no-any-return]
  File "/root/app.py", line 24, in home
    response = client.chat.completions.create(model="gpt-3.5-turbo",
  File "/usr/local/lib/python3.9/dist-packages/openai/_utils/_utils.py", line 271, in wrapper
    return func(*args, **kwargs)
  File "/usr/local/lib/python3.9/dist-packages/openai/resources/chat/completions.py", line 659, in create
    return self._post(
  File "/usr/local/lib/python3.9/dist-packages/openai/_base_client.py", line 1200, in post
    return cast(ResponseT, self.request(cast_to, opts, stream=stream, stream_cls=stream_cls))
  File "/usr/local/lib/python3.9/dist-packages/openai/_base_client.py", line 889, in request
    return self._request(
  File "/usr/local/lib/python3.9/dist-packages/openai/_base_client.py", line 980, in _request
    raise self._make_status_error_from_response(err.response) from None
openai.AuthenticationError: Error code: 401 - {'error': {'message': 'Incorrect API key provided: sua_chav*********aqui. You can find your API key at https://platform.openai.com/account/api-keys.', 'type': 'invalid_request_error', 'param': None, 'code': 'invalid_api_key'}}
192.168.0.181 - - [06/Feb/2024 02:17:41] "[36mGET /?__debugger__=yes&cmd=resource&f=style.css HTTP/1.1[0m" 304 -
192.168.0.181 - - [06/Feb/2024 02:17:41] "[36mGET /?__debugger__=yes&cmd=resource&f=debugger.js HTTP/1.1[0m" 304 -
192.168.0.181 - - [06/Feb/2024 02:17:41] "[36mGET /?__debugger__=yes&cmd=resource&f=console.png HTTP/1.1[0m" 304 -
 * Serving Flask app 'app'
 * Debug mode: on
Address already in use
Port 5000 is in use by another program. Either identify and stop that program, or start the server with a different port.
192.168.0.181 - - [06/Feb/2024 02:19:50] "GET / HTTP/1.1" 200 -
192.168.0.181 - - [06/Feb/2024 02:19:56] "[35m[1mPOST / HTTP/1.1[0m" 500 -
Traceback (most recent call last):
  File "/usr/local/lib/python3.9/dist-packages/flask/app.py", line 1488, in __call__
    return self.wsgi_app(environ, start_response)
  File "/usr/local/lib/python3.9/dist-packages/flask/app.py", line 1466, in wsgi_app
    response = self.handle_exception(e)
  File "/usr/local/lib/python3.9/dist-packages/flask/app.py", line 1463, in wsgi_app
    response = self.full_dispatch_request()
  File "/usr/local/lib/python3.9/dist-packages/flask/app.py", line 872, in full_dispatch_request
    rv = self.handle_user_exception(e)
  File "/usr/local/lib/python3.9/dist-packages/flask/app.py", line 870, in full_dispatch_request
    rv = self.dispatch_request()
  File "/usr/local/lib/python3.9/dist-packages/flask/app.py", line 855, in dispatch_request
    return self.ensure_sync(self.view_functions[rule.endpoint])(**view_args)  # type: ignore[no-any-return]
  File "/root/app.py", line 24, in home
    response = client.chat.completions.create(model="gpt-3.5-turbo",
  File "/usr/local/lib/python3.9/dist-packages/openai/_utils/_utils.py", line 271, in wrapper
    return func(*args, **kwargs)
  File "/usr/local/lib/python3.9/dist-packages/openai/resources/chat/completions.py", line 659, in create
    return self._post(
  File "/usr/local/lib/python3.9/dist-packages/openai/_base_client.py", line 1200, in post
    return cast(ResponseT, self.request(cast_to, opts, stream=stream, stream_cls=stream_cls))
  File "/usr/local/lib/python3.9/dist-packages/openai/_base_client.py", line 889, in request
    return self._request(
  File "/usr/local/lib/python3.9/dist-packages/openai/_base_client.py", line 980, in _request
    raise self._make_status_error_from_response(err.response) from None
openai.AuthenticationError: Error code: 401 - {'error': {'message': 'Incorrect API key provided: sua_chav*********aqui. You can find your API key at https://platform.openai.com/account/api-keys.', 'type': 'invalid_request_error', 'param': None, 'code': 'invalid_api_key'}}
192.168.0.181 - - [06/Feb/2024 02:19:56] "[36mGET /?__debugger__=yes&cmd=resource&f=debugger.js HTTP/1.1[0m" 304 -
192.168.0.181 - - [06/Feb/2024 02:19:56] "[36mGET /?__debugger__=yes&cmd=resource&f=style.css HTTP/1.1[0m" 304 -
192.168.0.181 - - [06/Feb/2024 02:19:56] "[36mGET /?__debugger__=yes&cmd=resource&f=console.png HTTP/1.1[0m" 304 -
192.168.0.181 - - [06/Feb/2024 09:55:33] "GET / HTTP/1.1" 200 -
192.168.0.181 - - [06/Feb/2024 09:55:33] "GET / HTTP/1.1" 200 -
192.168.0.181 - - [06/Feb/2024 09:55:34] "GET / HTTP/1.1" 200 -
192.168.0.181 - - [06/Feb/2024 11:41:27] "GET / HTTP/1.1" 200 -
192.168.0.181 - - [06/Feb/2024 11:41:27] "[33mGET /favicon.ico HTTP/1.1[0m" 404 -
192.168.0.181 - - [06/Feb/2024 11:41:33] "[35m[1mPOST / HTTP/1.1[0m" 500 -
Traceback (most recent call last):
  File "/usr/local/lib/python3.9/dist-packages/flask/app.py", line 1488, in __call__
    return self.wsgi_app(environ, start_response)
  File "/usr/local/lib/python3.9/dist-packages/flask/app.py", line 1466, in wsgi_app
    response = self.handle_exception(e)
  File "/usr/local/lib/python3.9/dist-packages/flask/app.py", line 1463, in wsgi_app
    response = self.full_dispatch_request()
  File "/usr/local/lib/python3.9/dist-packages/flask/app.py", line 872, in full_dispatch_request
    rv = self.handle_user_exception(e)
  File "/usr/local/lib/python3.9/dist-packages/flask/app.py", line 870, in full_dispatch_request
    rv = self.dispatch_request()
  File "/usr/local/lib/python3.9/dist-packages/flask/app.py", line 855, in dispatch_request
    return self.ensure_sync(self.view_functions[rule.endpoint])(**view_args)  # type: ignore[no-any-return]
  File "/root/app.py", line 24, in home
    response = client.chat.completions.create(model="gpt-3.5-turbo",
  File "/usr/local/lib/python3.9/dist-packages/openai/_utils/_utils.py", line 271, in wrapper
    return func(*args, **kwargs)
  File "/usr/local/lib/python3.9/dist-packages/openai/resources/chat/completions.py", line 659, in create
    return self._post(
  File "/usr/local/lib/python3.9/dist-packages/openai/_base_client.py", line 1200, in post
    return cast(ResponseT, self.request(cast_to, opts, stream=stream, stream_cls=stream_cls))
  File "/usr/local/lib/python3.9/dist-packages/openai/_base_client.py", line 889, in request
    return self._request(
  File "/usr/local/lib/python3.9/dist-packages/openai/_base_client.py", line 980, in _request
    raise self._make_status_error_from_response(err.response) from None
openai.AuthenticationError: Error code: 401 - {'error': {'message': 'Incorrect API key provided: sua_chav*********aqui. You can find your API key at https://platform.openai.com/account/api-keys.', 'type': 'invalid_request_error', 'param': None, 'code': 'invalid_api_key'}}
192.168.0.181 - - [06/Feb/2024 11:41:33] "[36mGET /?__debugger__=yes&cmd=resource&f=style.css HTTP/1.1[0m" 304 -
192.168.0.181 - - [06/Feb/2024 11:41:33] "[36mGET /?__debugger__=yes&cmd=resource&f=debugger.js HTTP/1.1[0m" 304 -
192.168.0.181 - - [06/Feb/2024 11:41:33] "[36mGET /?__debugger__=yes&cmd=resource&f=console.png HTTP/1.1[0m" 304 -
 * Serving Flask app 'app'
 * Debug mode: on
[31m[1mWARNING: This is a development server. Do not use it in a production deployment. Use a production WSGI server instead.[0m
 * Running on all addresses (0.0.0.0)
 * Running on http://127.0.0.1:5000
 * Running on http://192.168.0.28:5000
[33mPress CTRL+C to quit[0m
 * Restarting with stat
 * Debugger is active!
 * Debugger PIN: 729-843-404
192.168.0.181 - - [06/Feb/2024 12:24:49] "GET / HTTP/1.1" 200 -
192.168.0.181 - - [06/Feb/2024 12:24:56] "[35m[1mPOST / HTTP/1.1[0m" 500 -
Traceback (most recent call last):
  File "/usr/local/lib/python3.9/dist-packages/flask/app.py", line 1488, in __call__
    return self.wsgi_app(environ, start_response)
  File "/usr/local/lib/python3.9/dist-packages/flask/app.py", line 1466, in wsgi_app
    response = self.handle_exception(e)
  File "/usr/local/lib/python3.9/dist-packages/flask/app.py", line 1463, in wsgi_app
    response = self.full_dispatch_request()
  File "/usr/local/lib/python3.9/dist-packages/flask/app.py", line 872, in full_dispatch_request
    rv = self.handle_user_exception(e)
  File "/usr/local/lib/python3.9/dist-packages/flask/app.py", line 870, in full_dispatch_request
    rv = self.dispatch_request()
  File "/usr/local/lib/python3.9/dist-packages/flask/app.py", line 855, in dispatch_request
    return self.ensure_sync(self.view_functions[rule.endpoint])(**view_args)  # type: ignore[no-any-return]
  File "/root/app.py", line 22, in home
    response = client.chat.completions.create(model="gpt-3.5-turbo",
  File "/usr/local/lib/python3.9/dist-packages/openai/_utils/_utils.py", line 271, in wrapper
    return func(*args, **kwargs)
  File "/usr/local/lib/python3.9/dist-packages/openai/resources/chat/completions.py", line 659, in create
    return self._post(
  File "/usr/local/lib/python3.9/dist-packages/openai/_base_client.py", line 1200, in post
    return cast(ResponseT, self.request(cast_to, opts, stream=stream, stream_cls=stream_cls))
  File "/usr/local/lib/python3.9/dist-packages/openai/_base_client.py", line 889, in request
    return self._request(
  File "/usr/local/lib/python3.9/dist-packages/openai/_base_client.py", line 980, in _request
    raise self._make_status_error_from_response(err.response) from None
openai.AuthenticationError: Error code: 401 - {'error': {'message': 'Incorrect API key provided: sua_chav*********aqui. You can find your API key at https://platform.openai.com/account/api-keys.', 'type': 'invalid_request_error', 'param': None, 'code': 'invalid_api_key'}}
192.168.0.181 - - [06/Feb/2024 12:24:56] "[36mGET /?__debugger__=yes&cmd=resource&f=style.css HTTP/1.1[0m" 304 -
192.168.0.181 - - [06/Feb/2024 12:24:56] "[36mGET /?__debugger__=yes&cmd=resource&f=debugger.js HTTP/1.1[0m" 304 -
192.168.0.181 - - [06/Feb/2024 12:24:57] "[36mGET /?__debugger__=yes&cmd=resource&f=console.png HTTP/1.1[0m" 304 -
192.168.0.181 - - [06/Feb/2024 12:24:57] "[36mGET /?__debugger__=yes&cmd=resource&f=console.png HTTP/1.1[0m" 304 -
 * Detected change in '/root/app.py', reloading
 * Restarting with stat
 * Debugger is active!
 * Debugger PIN: 729-843-404
 * Serving Flask app 'app'
 * Debug mode: on
Address already in use
Port 5000 is in use by another program. Either identify and stop that program, or start the server with a different port.
192.168.0.181 - - [06/Feb/2024 12:34:12] "GET / HTTP/1.1" 200 -
192.168.0.181 - - [06/Feb/2024 12:34:19] "POST / HTTP/1.1" 200 -
192.168.0.181 - - [06/Feb/2024 12:34:50] "POST / HTTP/1.1" 200 -
192.168.0.181 - - [06/Feb/2024 12:35:25] "POST / HTTP/1.1" 200 -
192.168.0.181 - - [06/Feb/2024 12:36:52] "GET / HTTP/1.1" 200 -
192.168.0.181 - - [06/Feb/2024 12:39:39] "GET / HTTP/1.1" 200 -
192.168.0.181 - - [06/Feb/2024 12:40:18] "GET / HTTP/1.1" 200 -
192.168.0.181 - - [06/Feb/2024 12:40:19] "[33mGET /favicon.ico HTTP/1.1[0m" 404 -
192.168.0.181 - - [06/Feb/2024 12:43:33] "POST / HTTP/1.1" 200 -
192.168.0.181 - - [06/Feb/2024 12:43:47] "GET / HTTP/1.1" 200 -
192.168.0.181 - - [06/Feb/2024 12:43:48] "[33mGET /favicon.ico HTTP/1.1[0m" 404 -
192.168.0.181 - - [06/Feb/2024 12:44:00] "POST / HTTP/1.1" 200 -
192.168.0.181 - - [06/Feb/2024 12:44:01] "POST / HTTP/1.1" 200 -
192.168.0.181 - - [06/Feb/2024 12:44:08] "POST / HTTP/1.1" 200 -
192.168.0.181 - - [06/Feb/2024 12:44:30] "POST / HTTP/1.1" 200 -
192.168.0.181 - - [06/Feb/2024 12:44:37] "POST / HTTP/1.1" 200 -
 * Detected change in '/root/app.py', reloading
 * Restarting with stat
  File "/root/app.py", line 13
    Authorization: Bearer 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
                          ^
SyntaxError: invalid syntax
  File "/root/app.py", line 13
    Authorization: Bearer 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
                          ^
SyntaxError: invalid syntax
  File "/root/app.py", line 13
    Authorization: Bearer "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"
                          ^
SyntaxError: invalid syntax
 * Serving Flask app 'app'
 * Debug mode: on
[31m[1mWARNING: This is a development server. Do not use it in a production deployment. Use a production WSGI server instead.[0m
 * Running on all addresses (0.0.0.0)
 * Running on http://127.0.0.1:5000
 * Running on http://192.168.0.28:5000
[33mPress CTRL+C to quit[0m
 * Restarting with stat
 * Debugger is active!
 * Debugger PIN: 729-843-404
 * Serving Flask app 'app'
 * Debug mode: on
Address already in use
Port 5000 is in use by another program. Either identify and stop that program, or start the server with a different port.
 * Serving Flask app 'app'
 * Debug mode: on
Address already in use
Port 5000 is in use by another program. Either identify and stop that program, or start the server with a different port.
192.168.0.181 - - [06/Feb/2024 13:16:15] "GET / HTTP/1.1" 200 -
192.168.0.181 - - [06/Feb/2024 13:16:15] "[33mGET /favicon.ico HTTP/1.1[0m" 404 -
 * Detected change in '/root/app.py', reloading
 * Restarting with stat
 * Debugger is active!
 * Debugger PIN: 729-843-404
192.168.0.181 - - [06/Feb/2024 13:52:44] "GET / HTTP/1.1" 200 -
192.168.0.181 - - [06/Feb/2024 13:52:47] "GET / HTTP/1.1" 200 -
192.168.0.181 - - [06/Feb/2024 13:53:01] "POST / HTTP/1.1" 200 -
192.168.0.181 - - [06/Feb/2024 15:29:49] "GET / HTTP/1.1" 200 -
192.168.0.181 - - [06/Feb/2024 15:29:50] "[33mGET /favicon.ico HTTP/1.1[0m" 404 -
192.168.0.181 - - [06/Feb/2024 15:30:11] "POST / HTTP/1.1" 200 -
192.168.0.181 - - [06/Feb/2024 15:30:54] "POST / HTTP/1.1" 200 -
192.168.0.181 - - [06/Feb/2024 15:33:06] "POST / HTTP/1.1" 200 -
192.168.0.181 - - [06/Feb/2024 15:39:06] "GET / HTTP/1.1" 200 -
 * Serving Flask app 'app'
 * Debug mode: on
[31m[1mWARNING: This is a development server. Do not use it in a production deployment. Use a production WSGI server instead.[0m
 * Running on all addresses (0.0.0.0)
 * Running on http://127.0.0.1:5000
 * Running on http://192.168.0.28:5000
[33mPress CTRL+C to quit[0m
 * Restarting with stat
 * Debugger is active!
 * Debugger PIN: 480-715-215
192.168.0.181 - - [06/Feb/2024 17:02:42] "GET / HTTP/1.1" 200 -
192.168.0.181 - - [06/Feb/2024 17:02:42] "[33mGET /favicon.ico HTTP/1.1[0m" 404 -
192.168.0.181 - - [06/Feb/2024 17:16:52] "GET / HTTP/1.1" 200 -
192.168.0.181 - - [06/Feb/2024 17:26:49] "GET / HTTP/1.1" 200 -
 * Serving Flask app 'app'
 * Debug mode: on
Address already in use
Port 5000 is in use by another program. Either identify and stop that program, or start the server with a different port.
 * Serving Flask app 'app'
 * Debug mode: on
Address already in use
Port 5000 is in use by another program. Either identify and stop that program, or start the server with a different port.
 * Serving Flask app 'app'
 * Debug mode: on
[31m[1mWARNING: This is a development server. Do not use it in a production deployment. Use a production WSGI server instead.[0m
 * Running on all addresses (0.0.0.0)
 * Running on http://127.0.0.1:5000
 * Running on http://192.168.0.28:5000
[33mPress CTRL+C to quit[0m
 * Restarting with stat
 * Debugger is active!
 * Debugger PIN: 480-715-215
 * Serving Flask app 'app'
 * Debug mode: on
Address already in use
Port 5000 is in use by another program. Either identify and stop that program, or start the server with a different port.
 * Serving Flask app 'app'
 * Debug mode: on
Address already in use
Port 5000 is in use by another program. Either identify and stop that program, or start the server with a different port.
192.168.0.181 - - [06/Feb/2024 18:27:38] "GET / HTTP/1.1" 200 -
192.168.0.181 - - [06/Feb/2024 18:27:38] "[33mGET /favicon.ico HTTP/1.1[0m" 404 -
192.168.0.181 - - [06/Feb/2024 18:27:46] "[35m[1mPOST / HTTP/1.1[0m" 500 -
Traceback (most recent call last):
  File "/usr/local/lib/python3.9/dist-packages/flask/app.py", line 1488, in __call__
    return self.wsgi_app(environ, start_response)
  File "/usr/local/lib/python3.9/dist-packages/flask/app.py", line 1466, in wsgi_app
    response = self.handle_exception(e)
  File "/usr/local/lib/python3.9/dist-packages/flask/app.py", line 1463, in wsgi_app
    response = self.full_dispatch_request()
  File "/usr/local/lib/python3.9/dist-packages/flask/app.py", line 872, in full_dispatch_request
    rv = self.handle_user_exception(e)
  File "/usr/local/lib/python3.9/dist-packages/flask/app.py", line 870, in full_dispatch_request
    rv = self.dispatch_request()
  File "/usr/local/lib/python3.9/dist-packages/flask/app.py", line 855, in dispatch_request
    return self.ensure_sync(self.view_functions[rule.endpoint])(**view_args)  # type: ignore[no-any-return]
  File "/root/app.py", line 25, in home
    response = client.chat.completions.create(model="gpt-3.5-turbo",
  File "/usr/local/lib/python3.9/dist-packages/openai/_utils/_utils.py", line 271, in wrapper
    return func(*args, **kwargs)
  File "/usr/local/lib/python3.9/dist-packages/openai/resources/chat/completions.py", line 659, in create
    return self._post(
  File "/usr/local/lib/python3.9/dist-packages/openai/_base_client.py", line 1200, in post
    return cast(ResponseT, self.request(cast_to, opts, stream=stream, stream_cls=stream_cls))
  File "/usr/local/lib/python3.9/dist-packages/openai/_base_client.py", line 889, in request
    return self._request(
  File "/usr/local/lib/python3.9/dist-packages/openai/_base_client.py", line 980, in _request
    raise self._make_status_error_from_response(err.response) from None
openai.AuthenticationError: Error code: 401 - {'error': {'message': 'Incorrect API key provided: sua_chav*********aqui. You can find your API key at https://platform.openai.com/account/api-keys.', 'type': 'invalid_request_error', 'param': None, 'code': 'invalid_api_key'}}
192.168.0.181 - - [06/Feb/2024 18:27:46] "GET /?__debugger__=yes&cmd=resource&f=style.css HTTP/1.1" 200 -
192.168.0.181 - - [06/Feb/2024 18:27:46] "GET /?__debugger__=yes&cmd=resource&f=debugger.js HTTP/1.1" 200 -
192.168.0.181 - - [06/Feb/2024 18:27:46] "GET /?__debugger__=yes&cmd=resource&f=console.png HTTP/1.1" 200 -
192.168.0.181 - - [06/Feb/2024 18:27:46] "[36mGET /?__debugger__=yes&cmd=resource&f=console.png HTTP/1.1[0m" 304 -
 * Serving Flask app 'app'
 * Debug mode: on
Address already in use
Port 5000 is in use by another program. Either identify and stop that program, or start the server with a different port.
192.168.0.181 - - [06/Feb/2024 18:33:57] "GET / HTTP/1.1" 200 -
192.168.0.181 - - [06/Feb/2024 18:34:02] "[35m[1mPOST / HTTP/1.1[0m" 500 -
Traceback (most recent call last):
  File "/usr/local/lib/python3.9/dist-packages/flask/app.py", line 1488, in __call__
    return self.wsgi_app(environ, start_response)
  File "/usr/local/lib/python3.9/dist-packages/flask/app.py", line 1466, in wsgi_app
    response = self.handle_exception(e)
  File "/usr/local/lib/python3.9/dist-packages/flask/app.py", line 1463, in wsgi_app
    response = self.full_dispatch_request()
  File "/usr/local/lib/python3.9/dist-packages/flask/app.py", line 872, in full_dispatch_request
    rv = self.handle_user_exception(e)
  File "/usr/local/lib/python3.9/dist-packages/flask/app.py", line 870, in full_dispatch_request
    rv = self.dispatch_request()
  File "/usr/local/lib/python3.9/dist-packages/flask/app.py", line 855, in dispatch_request
    return self.ensure_sync(self.view_functions[rule.endpoint])(**view_args)  # type: ignore[no-any-return]
  File "/root/app.py", line 25, in home
    response = client.chat.completions.create(model="gpt-3.5-turbo",
  File "/usr/local/lib/python3.9/dist-packages/openai/_utils/_utils.py", line 271, in wrapper
    return func(*args, **kwargs)
  File "/usr/local/lib/python3.9/dist-packages/openai/resources/chat/completions.py", line 659, in create
    return self._post(
  File "/usr/local/lib/python3.9/dist-packages/openai/_base_client.py", line 1200, in post
    return cast(ResponseT, self.request(cast_to, opts, stream=stream, stream_cls=stream_cls))
  File "/usr/local/lib/python3.9/dist-packages/openai/_base_client.py", line 889, in request
    return self._request(
  File "/usr/local/lib/python3.9/dist-packages/openai/_base_client.py", line 980, in _request
    raise self._make_status_error_from_response(err.response) from None
openai.AuthenticationError: Error code: 401 - {'error': {'message': 'Incorrect API key provided: sua_chav*********aqui. You can find your API key at https://platform.openai.com/account/api-keys.', 'type': 'invalid_request_error', 'param': None, 'code': 'invalid_api_key'}}
192.168.0.181 - - [06/Feb/2024 18:34:02] "[36mGET /?__debugger__=yes&cmd=resource&f=style.css HTTP/1.1[0m" 304 -
192.168.0.181 - - [06/Feb/2024 18:34:02] "[36mGET /?__debugger__=yes&cmd=resource&f=debugger.js HTTP/1.1[0m" 304 -
192.168.0.181 - - [06/Feb/2024 18:34:02] "[36mGET /?__debugger__=yes&cmd=resource&f=console.png HTTP/1.1[0m" 304 -
 * Serving Flask app 'app'
 * Debug mode: on
Address already in use
Port 5000 is in use by another program. Either identify and stop that program, or start the server with a different port.
192.168.0.181 - - [06/Feb/2024 18:37:34] "GET / HTTP/1.1" 200 -
192.168.0.181 - - [06/Feb/2024 18:37:40] "[35m[1mPOST / HTTP/1.1[0m" 500 -
Traceback (most recent call last):
  File "/usr/local/lib/python3.9/dist-packages/flask/app.py", line 1488, in __call__
    return self.wsgi_app(environ, start_response)
  File "/usr/local/lib/python3.9/dist-packages/flask/app.py", line 1466, in wsgi_app
    response = self.handle_exception(e)
  File "/usr/local/lib/python3.9/dist-packages/flask/app.py", line 1463, in wsgi_app
    response = self.full_dispatch_request()
  File "/usr/local/lib/python3.9/dist-packages/flask/app.py", line 872, in full_dispatch_request
    rv = self.handle_user_exception(e)
  File "/usr/local/lib/python3.9/dist-packages/flask/app.py", line 870, in full_dispatch_request
    rv = self.dispatch_request()
  File "/usr/local/lib/python3.9/dist-packages/flask/app.py", line 855, in dispatch_request
    return self.ensure_sync(self.view_functions[rule.endpoint])(**view_args)  # type: ignore[no-any-return]
  File "/root/app.py", line 25, in home
    response = client.chat.completions.create(model="gpt-3.5-turbo",
  File "/usr/local/lib/python3.9/dist-packages/openai/_utils/_utils.py", line 271, in wrapper
    return func(*args, **kwargs)
  File "/usr/local/lib/python3.9/dist-packages/openai/resources/chat/completions.py", line 659, in create
    return self._post(
  File "/usr/local/lib/python3.9/dist-packages/openai/_base_client.py", line 1200, in post
    return cast(ResponseT, self.request(cast_to, opts, stream=stream, stream_cls=stream_cls))
  File "/usr/local/lib/python3.9/dist-packages/openai/_base_client.py", line 889, in request
    return self._request(
  File "/usr/local/lib/python3.9/dist-packages/openai/_base_client.py", line 980, in _request
    raise self._make_status_error_from_response(err.response) from None
openai.AuthenticationError: Error code: 401 - {'error': {'message': 'Incorrect API key provided: sua_chav*********aqui. You can find your API key at https://platform.openai.com/account/api-keys.', 'type': 'invalid_request_error', 'param': None, 'code': 'invalid_api_key'}}
192.168.0.181 - - [06/Feb/2024 18:37:40] "[36mGET /?__debugger__=yes&cmd=resource&f=debugger.js HTTP/1.1[0m" 304 -
192.168.0.181 - - [06/Feb/2024 18:37:40] "[36mGET /?__debugger__=yes&cmd=resource&f=style.css HTTP/1.1[0m" 304 -
192.168.0.181 - - [06/Feb/2024 18:37:40] "[36mGET /?__debugger__=yes&cmd=resource&f=console.png HTTP/1.1[0m" 304 -
 * Serving Flask app 'app'
 * Debug mode: on
[31m[1mWARNING: This is a development server. Do not use it in a production deployment. Use a production WSGI server instead.[0m
 * Running on all addresses (0.0.0.0)
 * Running on http://127.0.0.1:5000
 * Running on http://192.168.0.28:5000
[33mPress CTRL+C to quit[0m
 * Restarting with stat
 * Debugger is active!
 * Debugger PIN: 480-715-215
192.168.0.181 - - [06/Feb/2024 18:42:02] "GET / HTTP/1.1" 200 -
192.168.0.181 - - [06/Feb/2024 18:42:08] "[35m[1mPOST / HTTP/1.1[0m" 500 -
Traceback (most recent call last):
  File "/usr/local/lib/python3.9/dist-packages/flask/app.py", line 1488, in __call__
    return self.wsgi_app(environ, start_response)
  File "/usr/local/lib/python3.9/dist-packages/flask/app.py", line 1466, in wsgi_app
    response = self.handle_exception(e)
  File "/usr/local/lib/python3.9/dist-packages/flask/app.py", line 1463, in wsgi_app
    response = self.full_dispatch_request()
  File "/usr/local/lib/python3.9/dist-packages/flask/app.py", line 872, in full_dispatch_request
    rv = self.handle_user_exception(e)
  File "/usr/local/lib/python3.9/dist-packages/flask/app.py", line 870, in full_dispatch_request
    rv = self.dispatch_request()
  File "/usr/local/lib/python3.9/dist-packages/flask/app.py", line 855, in dispatch_request
    return self.ensure_sync(self.view_functions[rule.endpoint])(**view_args)  # type: ignore[no-any-return]
  File "/root/app.py", line 25, in home
    response = client.chat.completions.create(model="gpt-3.5-turbo",
  File "/usr/local/lib/python3.9/dist-packages/openai/_utils/_utils.py", line 271, in wrapper
    return func(*args, **kwargs)
  File "/usr/local/lib/python3.9/dist-packages/openai/resources/chat/completions.py", line 659, in create
    return self._post(
  File "/usr/local/lib/python3.9/dist-packages/openai/_base_client.py", line 1200, in post
    return cast(ResponseT, self.request(cast_to, opts, stream=stream, stream_cls=stream_cls))
  File "/usr/local/lib/python3.9/dist-packages/openai/_base_client.py", line 889, in request
    return self._request(
  File "/usr/local/lib/python3.9/dist-packages/openai/_base_client.py", line 980, in _request
    raise self._make_status_error_from_response(err.response) from None
openai.AuthenticationError: Error code: 401 - {'error': {'message': 'Incorrect API key provided: sua_chav*********aqui. You can find your API key at https://platform.openai.com/account/api-keys.', 'type': 'invalid_request_error', 'param': None, 'code': 'invalid_api_key'}}
192.168.0.181 - - [06/Feb/2024 18:42:08] "[36mGET /?__debugger__=yes&cmd=resource&f=style.css HTTP/1.1[0m" 304 -
192.168.0.181 - - [06/Feb/2024 18:42:08] "[36mGET /?__debugger__=yes&cmd=resource&f=debugger.js HTTP/1.1[0m" 304 -
192.168.0.181 - - [06/Feb/2024 18:42:08] "[36mGET /?__debugger__=yes&cmd=resource&f=console.png HTTP/1.1[0m" 304 -
192.168.0.181 - - [06/Feb/2024 18:42:08] "[36mGET /?__debugger__=yes&cmd=resource&f=console.png HTTP/1.1[0m" 304 -
192.168.0.181 - - [06/Feb/2024 18:42:10] "GET / HTTP/1.1" 200 -
 * Detected change in '/root/app.py', reloading
 * Restarting with stat
 * Debugger is active!
 * Debugger PIN: 480-715-215
192.168.0.181 - - [06/Feb/2024 18:44:10] "POST / HTTP/1.1" 200 -
192.168.0.181 - - [06/Feb/2024 18:44:27] "POST / HTTP/1.1" 200 -
192.168.0.181 - - [06/Feb/2024 18:44:45] "POST / HTTP/1.1" 200 -
 * Detected change in '/root/app.py', reloading
 * Restarting with stat
 * Debugger is active!
 * Debugger PIN: 480-715-215
192.168.0.181 - - [06/Feb/2024 18:57:29] "GET / HTTP/1.1" 200 -
192.168.0.181 - - [06/Feb/2024 18:57:33] "GET / HTTP/1.1" 200 -
192.168.0.181 - - [06/Feb/2024 18:57:45] "[35m[1mPOST / HTTP/1.1[0m" 500 -
Traceback (most recent call last):
  File "/usr/local/lib/python3.9/dist-packages/flask/app.py", line 1488, in __call__
    return self.wsgi_app(environ, start_response)
  File "/usr/local/lib/python3.9/dist-packages/flask/app.py", line 1466, in wsgi_app
    response = self.handle_exception(e)
  File "/usr/local/lib/python3.9/dist-packages/flask/app.py", line 1463, in wsgi_app
    response = self.full_dispatch_request()
  File "/usr/local/lib/python3.9/dist-packages/flask/app.py", line 872, in full_dispatch_request
    rv = self.handle_user_exception(e)
  File "/usr/local/lib/python3.9/dist-packages/flask/app.py", line 870, in full_dispatch_request
    rv = self.dispatch_request()
  File "/usr/local/lib/python3.9/dist-packages/flask/app.py", line 855, in dispatch_request
    return self.ensure_sync(self.view_functions[rule.endpoint])(**view_args)  # type: ignore[no-any-return]
  File "/root/app.py", line 25, in home
    response = client.chat.completions.create(model="gpt-3.5-turbo",
  File "/usr/local/lib/python3.9/dist-packages/openai/_utils/_utils.py", line 271, in wrapper
    return func(*args, **kwargs)
  File "/usr/local/lib/python3.9/dist-packages/openai/resources/chat/completions.py", line 659, in create
    return self._post(
  File "/usr/local/lib/python3.9/dist-packages/openai/_base_client.py", line 1200, in post
    return cast(ResponseT, self.request(cast_to, opts, stream=stream, stream_cls=stream_cls))
  File "/usr/local/lib/python3.9/dist-packages/openai/_base_client.py", line 889, in request
    return self._request(
  File "/usr/local/lib/python3.9/dist-packages/openai/_base_client.py", line 980, in _request
    raise self._make_status_error_from_response(err.response) from None
openai.AuthenticationError: Error code: 401 - {'error': {'message': 'Incorrect API key provided: sua_chav*********aqui. You can find your API key at https://platform.openai.com/account/api-keys.', 'type': 'invalid_request_error', 'param': None, 'code': 'invalid_api_key'}}
192.168.0.181 - - [06/Feb/2024 18:57:45] "[36mGET /?__debugger__=yes&cmd=resource&f=debugger.js HTTP/1.1[0m" 304 -
192.168.0.181 - - [06/Feb/2024 18:57:45] "[36mGET /?__debugger__=yes&cmd=resource&f=style.css HTTP/1.1[0m" 304 -
192.168.0.181 - - [06/Feb/2024 18:57:45] "[36mGET /?__debugger__=yes&cmd=resource&f=console.png HTTP/1.1[0m" 304 -
192.168.0.181 - - [06/Feb/2024 18:57:46] "[36mGET /?__debugger__=yes&cmd=resource&f=console.png HTTP/1.1[0m" 304 -
 * Serving Flask app 'app'
 * Debug mode: on
Address already in use
Port 5000 is in use by another program. Either identify and stop that program, or start the server with a different port.
192.168.0.181 - - [06/Feb/2024 18:58:33] "GET / HTTP/1.1" 200 -
192.168.0.181 - - [06/Feb/2024 18:58:41] "[35m[1mPOST / HTTP/1.1[0m" 500 -
Traceback (most recent call last):
  File "/usr/local/lib/python3.9/dist-packages/flask/app.py", line 1488, in __call__
    return self.wsgi_app(environ, start_response)
  File "/usr/local/lib/python3.9/dist-packages/flask/app.py", line 1466, in wsgi_app
    response = self.handle_exception(e)
  File "/usr/local/lib/python3.9/dist-packages/flask/app.py", line 1463, in wsgi_app
    response = self.full_dispatch_request()
  File "/usr/local/lib/python3.9/dist-packages/flask/app.py", line 872, in full_dispatch_request
    rv = self.handle_user_exception(e)
  File "/usr/local/lib/python3.9/dist-packages/flask/app.py", line 870, in full_dispatch_request
    rv = self.dispatch_request()
  File "/usr/local/lib/python3.9/dist-packages/flask/app.py", line 855, in dispatch_request
    return self.ensure_sync(self.view_functions[rule.endpoint])(**view_args)  # type: ignore[no-any-return]
  File "/root/app.py", line 25, in home
    response = client.chat.completions.create(model="gpt-3.5-turbo",
  File "/usr/local/lib/python3.9/dist-packages/openai/_utils/_utils.py", line 271, in wrapper
    return func(*args, **kwargs)
  File "/usr/local/lib/python3.9/dist-packages/openai/resources/chat/completions.py", line 659, in create
    return self._post(
  File "/usr/local/lib/python3.9/dist-packages/openai/_base_client.py", line 1200, in post
    return cast(ResponseT, self.request(cast_to, opts, stream=stream, stream_cls=stream_cls))
  File "/usr/local/lib/python3.9/dist-packages/openai/_base_client.py", line 889, in request
    return self._request(
  File "/usr/local/lib/python3.9/dist-packages/openai/_base_client.py", line 980, in _request
    raise self._make_status_error_from_response(err.response) from None
openai.AuthenticationError: Error code: 401 - {'error': {'message': 'Incorrect API key provided: sua_chav*********aqui. You can find your API key at https://platform.openai.com/account/api-keys.', 'type': 'invalid_request_error', 'param': None, 'code': 'invalid_api_key'}}
192.168.0.181 - - [06/Feb/2024 18:58:41] "[36mGET /?__debugger__=yes&cmd=resource&f=debugger.js HTTP/1.1[0m" 304 -
192.168.0.181 - - [06/Feb/2024 18:58:41] "[36mGET /?__debugger__=yes&cmd=resource&f=style.css HTTP/1.1[0m" 304 -
192.168.0.181 - - [06/Feb/2024 18:58:41] "[36mGET /?__debugger__=yes&cmd=resource&f=console.png HTTP/1.1[0m" 304 -
 * Detected change in '/root/app.py', reloading
 * Restarting with stat
 * Debugger is active!
 * Debugger PIN: 480-715-215
192.168.0.181 - - [06/Feb/2024 19:01:53] "GET / HTTP/1.1" 200 -
192.168.0.181 - - [06/Feb/2024 19:02:18] "POST / HTTP/1.1" 200 -
 * Serving Flask app 'app'
 * Debug mode: on
Address already in use
Port 5000 is in use by another program. Either identify and stop that program, or start the server with a different port.
192.168.0.181 - - [06/Feb/2024 20:47:20] "GET / HTTP/1.1" 200 -
192.168.0.181 - - [06/Feb/2024 20:47:21] "[33mGET /favicon.ico HTTP/1.1[0m" 404 -
192.168.0.181 - - [06/Feb/2024 20:47:28] "POST / HTTP/1.1" 200 -
192.168.0.181 - - [06/Feb/2024 21:47:46] "GET / HTTP/1.1" 200 -
192.168.0.181 - - [06/Feb/2024 21:47:47] "[33mGET /favicon.ico HTTP/1.1[0m" 404 -
 * Detected change in '/root/app.py', reloading
 * Restarting with stat
 * Debugger is active!
 * Debugger PIN: 480-715-215
192.168.0.181 - - [06/Feb/2024 21:58:04] "GET / HTTP/1.1" 200 -
192.168.0.181 - - [06/Feb/2024 21:58:13] "[35m[1mPOST / HTTP/1.1[0m" 500 -
Traceback (most recent call last):
  File "/usr/local/lib/python3.9/dist-packages/flask/app.py", line 1488, in __call__
    return self.wsgi_app(environ, start_response)
  File "/usr/local/lib/python3.9/dist-packages/flask/app.py", line 1466, in wsgi_app
    response = self.handle_exception(e)
  File "/usr/local/lib/python3.9/dist-packages/flask/app.py", line 1463, in wsgi_app
    response = self.full_dispatch_request()
  File "/usr/local/lib/python3.9/dist-packages/flask/app.py", line 872, in full_dispatch_request
    rv = self.handle_user_exception(e)
  File "/usr/local/lib/python3.9/dist-packages/flask/app.py", line 870, in full_dispatch_request
    rv = self.dispatch_request()
  File "/usr/local/lib/python3.9/dist-packages/flask/app.py", line 855, in dispatch_request
    return self.ensure_sync(self.view_functions[rule.endpoint])(**view_args)  # type: ignore[no-any-return]
  File "/root/app.py", line 25, in home
    response = client.chat.completions.create(model="gpt-3.5-turbo",
  File "/usr/local/lib/python3.9/dist-packages/openai/_utils/_utils.py", line 271, in wrapper
    return func(*args, **kwargs)
  File "/usr/local/lib/python3.9/dist-packages/openai/resources/chat/completions.py", line 659, in create
    return self._post(
  File "/usr/local/lib/python3.9/dist-packages/openai/_base_client.py", line 1200, in post
    return cast(ResponseT, self.request(cast_to, opts, stream=stream, stream_cls=stream_cls))
  File "/usr/local/lib/python3.9/dist-packages/openai/_base_client.py", line 889, in request
    return self._request(
  File "/usr/local/lib/python3.9/dist-packages/openai/_base_client.py", line 980, in _request
    raise self._make_status_error_from_response(err.response) from None
openai.AuthenticationError: Error code: 401 - {'error': {'message': 'Incorrect API key provided: sua_chav*********aqui. You can find your API key at https://platform.openai.com/account/api-keys.', 'type': 'invalid_request_error', 'param': None, 'code': 'invalid_api_key'}}
192.168.0.181 - - [06/Feb/2024 21:58:13] "GET /?__debugger__=yes&cmd=resource&f=style.css HTTP/1.1" 200 -
192.168.0.181 - - [06/Feb/2024 21:58:13] "GET /?__debugger__=yes&cmd=resource&f=debugger.js HTTP/1.1" 200 -
192.168.0.181 - - [06/Feb/2024 21:58:13] "GET /?__debugger__=yes&cmd=resource&f=console.png HTTP/1.1" 200 -
192.168.0.181 - - [06/Feb/2024 21:58:13] "[36mGET /?__debugger__=yes&cmd=resource&f=console.png HTTP/1.1[0m" 304 -
192.168.0.181 - - [06/Feb/2024 21:59:41] "GET / HTTP/1.1" 200 -
192.168.0.181 - - [06/Feb/2024 21:59:46] "[35m[1mPOST / HTTP/1.1[0m" 500 -
Traceback (most recent call last):
  File "/usr/local/lib/python3.9/dist-packages/flask/app.py", line 1488, in __call__
    return self.wsgi_app(environ, start_response)
  File "/usr/local/lib/python3.9/dist-packages/flask/app.py", line 1466, in wsgi_app
    response = self.handle_exception(e)
  File "/usr/local/lib/python3.9/dist-packages/flask/app.py", line 1463, in wsgi_app
    response = self.full_dispatch_request()
  File "/usr/local/lib/python3.9/dist-packages/flask/app.py", line 872, in full_dispatch_request
    rv = self.handle_user_exception(e)
  File "/usr/local/lib/python3.9/dist-packages/flask/app.py", line 870, in full_dispatch_request
    rv = self.dispatch_request()
  File "/usr/local/lib/python3.9/dist-packages/flask/app.py", line 855, in dispatch_request
    return self.ensure_sync(self.view_functions[rule.endpoint])(**view_args)  # type: ignore[no-any-return]
  File "/root/app.py", line 25, in home
    response = client.chat.completions.create(model="gpt-3.5-turbo",
  File "/usr/local/lib/python3.9/dist-packages/openai/_utils/_utils.py", line 271, in wrapper
    return func(*args, **kwargs)
  File "/usr/local/lib/python3.9/dist-packages/openai/resources/chat/completions.py", line 659, in create
    return self._post(
  File "/usr/local/lib/python3.9/dist-packages/openai/_base_client.py", line 1200, in post
    return cast(ResponseT, self.request(cast_to, opts, stream=stream, stream_cls=stream_cls))
  File "/usr/local/lib/python3.9/dist-packages/openai/_base_client.py", line 889, in request
    return self._request(
  File "/usr/local/lib/python3.9/dist-packages/openai/_base_client.py", line 980, in _request
    raise self._make_status_error_from_response(err.response) from None
openai.AuthenticationError: Error code: 401 - {'error': {'message': 'Incorrect API key provided: sua_chav*********aqui. You can find your API key at https://platform.openai.com/account/api-keys.', 'type': 'invalid_request_error', 'param': None, 'code': 'invalid_api_key'}}
192.168.0.181 - - [06/Feb/2024 21:59:46] "[36mGET /?__debugger__=yes&cmd=resource&f=style.css HTTP/1.1[0m" 304 -
192.168.0.181 - - [06/Feb/2024 21:59:46] "[36mGET /?__debugger__=yes&cmd=resource&f=debugger.js HTTP/1.1[0m" 304 -
192.168.0.181 - - [06/Feb/2024 21:59:47] "[36mGET /?__debugger__=yes&cmd=resource&f=console.png HTTP/1.1[0m" 304 -
192.168.0.181 - - [06/Feb/2024 21:59:47] "[36mGET /?__debugger__=yes&cmd=resource&f=console.png HTTP/1.1[0m" 304 -
 * Serving Flask app 'app'
 * Debug mode: on
Address already in use
Port 5000 is in use by another program. Either identify and stop that program, or start the server with a different port.
192.168.0.181 - - [06/Feb/2024 22:00:24] "GET / HTTP/1.1" 200 -
192.168.0.181 - - [06/Feb/2024 22:00:26] "GET / HTTP/1.1" 200 -
192.168.0.181 - - [06/Feb/2024 22:00:26] "[33mGET /favicon.ico HTTP/1.1[0m" 404 -
192.168.0.181 - - [06/Feb/2024 22:00:32] "[35m[1mPOST / HTTP/1.1[0m" 500 -
Traceback (most recent call last):
  File "/usr/local/lib/python3.9/dist-packages/flask/app.py", line 1488, in __call__
    return self.wsgi_app(environ, start_response)
  File "/usr/local/lib/python3.9/dist-packages/flask/app.py", line 1466, in wsgi_app
    response = self.handle_exception(e)
  File "/usr/local/lib/python3.9/dist-packages/flask/app.py", line 1463, in wsgi_app
    response = self.full_dispatch_request()
  File "/usr/local/lib/python3.9/dist-packages/flask/app.py", line 872, in full_dispatch_request
    rv = self.handle_user_exception(e)
  File "/usr/local/lib/python3.9/dist-packages/flask/app.py", line 870, in full_dispatch_request
    rv = self.dispatch_request()
  File "/usr/local/lib/python3.9/dist-packages/flask/app.py", line 855, in dispatch_request
    return self.ensure_sync(self.view_functions[rule.endpoint])(**view_args)  # type: ignore[no-any-return]
  File "/root/app.py", line 25, in home
    response = client.chat.completions.create(model="gpt-3.5-turbo",
  File "/usr/local/lib/python3.9/dist-packages/openai/_utils/_utils.py", line 271, in wrapper
    return func(*args, **kwargs)
  File "/usr/local/lib/python3.9/dist-packages/openai/resources/chat/completions.py", line 659, in create
    return self._post(
  File "/usr/local/lib/python3.9/dist-packages/openai/_base_client.py", line 1200, in post
    return cast(ResponseT, self.request(cast_to, opts, stream=stream, stream_cls=stream_cls))
  File "/usr/local/lib/python3.9/dist-packages/openai/_base_client.py", line 889, in request
    return self._request(
  File "/usr/local/lib/python3.9/dist-packages/openai/_base_client.py", line 980, in _request
    raise self._make_status_error_from_response(err.response) from None
openai.AuthenticationError: Error code: 401 - {'error': {'message': 'Incorrect API key provided: sua_chav*********aqui. You can find your API key at https://platform.openai.com/account/api-keys.', 'type': 'invalid_request_error', 'param': None, 'code': 'invalid_api_key'}}
192.168.0.181 - - [06/Feb/2024 22:00:32] "[36mGET /?__debugger__=yes&cmd=resource&f=debugger.js HTTP/1.1[0m" 304 -
192.168.0.181 - - [06/Feb/2024 22:00:32] "[36mGET /?__debugger__=yes&cmd=resource&f=style.css HTTP/1.1[0m" 304 -
192.168.0.181 - - [06/Feb/2024 22:00:32] "[36mGET /?__debugger__=yes&cmd=resource&f=console.png HTTP/1.1[0m" 304 -
192.168.0.181 - - [06/Feb/2024 22:00:32] "[36mGET /?__debugger__=yes&cmd=resource&f=console.png HTTP/1.1[0m" 304 -
 * Detected change in '/root/app.py', reloading
 * Restarting with stat
Traceback (most recent call last):
  File "/root/app.py", line 16, in <module>
    openai.api_key=os.environ["OPENAI_API_KEY"]
NameError: name 'openai' is not defined
Traceback (most recent call last):
  File "/root/app.py", line 16, in <module>
    openai.api_key=os.environ["OPENAI_API_KEY"]
NameError: name 'openai' is not defined
Traceback (most recent call last):
  File "/root/app.py", line 16, in <module>
    openai.api_key=os.environ["OPENAI_API_KEY"]
NameError: name 'openai' is not defined
 * Serving Flask app 'app'
 * Debug mode: on
[31m[1mWARNING: This is a development server. Do not use it in a production deployment. Use a production WSGI server instead.[0m
 * Running on all addresses (0.0.0.0)
 * Running on http://127.0.0.1:5000
 * Running on http://192.168.0.28:5000
[33mPress CTRL+C to quit[0m
 * Restarting with stat
 * Debugger is active!
 * Debugger PIN: 729-843-404
192.168.0.181 - - [06/Feb/2024 22:18:05] "GET / HTTP/1.1" 200 -
192.168.0.181 - - [06/Feb/2024 22:19:11] "POST / HTTP/1.1" 200 -
192.168.0.181 - - [06/Feb/2024 22:24:16] "POST / HTTP/1.1" 200 -
192.168.0.181 - - [06/Feb/2024 22:24:16] "[33mGET /favicon.ico HTTP/1.1[0m" 404 -
192.168.0.181 - - [06/Feb/2024 22:24:22] "GET / HTTP/1.1" 200 -
192.168.0.181 - - [06/Feb/2024 22:32:33] "GET / HTTP/1.1" 200 -
192.168.0.181 - - [06/Feb/2024 22:32:36] "GET / HTTP/1.1" 200 -
192.168.0.181 - - [07/Feb/2024 14:19:22] "GET / HTTP/1.1" 200 -
192.168.0.181 - - [07/Feb/2024 14:19:23] "[33mGET /favicon.ico HTTP/1.1[0m" 404 -
192.168.0.181 - - [07/Feb/2024 14:20:14] "POST / HTTP/1.1" 200 -
192.168.0.181 - - [07/Feb/2024 18:51:46] "GET / HTTP/1.1" 200 -
192.168.0.181 - - [07/Feb/2024 18:52:06] "GET / HTTP/1.1" 200 -
192.168.0.181 - - [07/Feb/2024 18:52:12] "GET / HTTP/1.1" 200 -
192.168.0.181 - - [07/Feb/2024 18:53:19] "GET / HTTP/1.1" 200 -
192.168.0.181 - - [07/Feb/2024 18:53:20] "[33mGET /favicon.ico HTTP/1.1[0m" 404 -
192.168.0.181 - - [07/Feb/2024 18:53:48] "POST / HTTP/1.1" 200 -
192.168.0.181 - - [07/Feb/2024 18:57:17] "POST / HTTP/1.1" 200 -
192.168.0.181 - - [07/Feb/2024 18:57:22] "POST / HTTP/1.1" 200 -
192.168.0.181 - - [07/Feb/2024 18:57:26] "POST / HTTP/1.1" 200 -
192.168.0.181 - - [07/Feb/2024 18:57:26] "POST / HTTP/1.1" 200 -
192.168.0.181 - - [07/Feb/2024 18:57:27] "POST / HTTP/1.1" 200 -
192.168.0.181 - - [07/Feb/2024 18:57:29] "POST / HTTP/1.1" 200 -
192.168.0.181 - - [07/Feb/2024 18:57:29] "POST / HTTP/1.1" 200 -
192.168.0.181 - - [07/Feb/2024 18:57:30] "POST / HTTP/1.1" 200 -
192.168.0.181 - - [07/Feb/2024 18:57:31] "POST / HTTP/1.1" 200 -
192.168.0.181 - - [07/Feb/2024 18:57:33] "POST / HTTP/1.1" 200 -
192.168.0.181 - - [07/Feb/2024 18:57:36] "POST / HTTP/1.1" 200 -
192.168.0.181 - - [07/Feb/2024 20:54:20] "GET / HTTP/1.1" 200 -
192.168.0.181 - - [07/Feb/2024 20:54:20] "[33mGET /favicon.ico HTTP/1.1[0m" 404 -
192.168.0.181 - - [07/Feb/2024 20:54:43] "POST / HTTP/1.1" 200 -
192.168.0.181 - - [07/Feb/2024 20:58:12] "POST / HTTP/1.1" 200 -
192.168.0.181 - - [07/Feb/2024 21:01:41] "POST / HTTP/1.1" 200 -
192.168.0.181 - - [07/Feb/2024 21:04:08] "POST / HTTP/1.1" 200 -
192.168.0.181 - - [08/Feb/2024 12:41:11] "GET / HTTP/1.1" 200 -
192.168.0.181 - - [08/Feb/2024 12:41:11] "[33mGET /favicon.ico HTTP/1.1[0m" 404 -
192.168.0.181 - - [08/Feb/2024 13:52:41] "POST / HTTP/1.1" 200 -
192.168.0.181 - - [08/Feb/2024 13:54:49] "[35m[1mPOST / HTTP/1.1[0m" 500 -
Traceback (most recent call last):
  File "/usr/local/lib/python3.9/dist-packages/flask/app.py", line 1488, in __call__
    return self.wsgi_app(environ, start_response)
  File "/usr/local/lib/python3.9/dist-packages/flask/app.py", line 1466, in wsgi_app
    response = self.handle_exception(e)
  File "/usr/local/lib/python3.9/dist-packages/flask/app.py", line 1463, in wsgi_app
    response = self.full_dispatch_request()
  File "/usr/local/lib/python3.9/dist-packages/flask/app.py", line 872, in full_dispatch_request
    rv = self.handle_user_exception(e)
  File "/usr/local/lib/python3.9/dist-packages/flask/app.py", line 870, in full_dispatch_request
    rv = self.dispatch_request()
  File "/usr/local/lib/python3.9/dist-packages/flask/app.py", line 855, in dispatch_request
    return self.ensure_sync(self.view_functions[rule.endpoint])(**view_args)  # type: ignore[no-any-return]
  File "/root/app.py", line 25, in home
    response = client.chat.completions.create(model="gpt-3.5-turbo",
  File "/usr/local/lib/python3.9/dist-packages/openai/_utils/_utils.py", line 271, in wrapper
    return func(*args, **kwargs)
  File "/usr/local/lib/python3.9/dist-packages/openai/resources/chat/completions.py", line 659, in create
    return self._post(
  File "/usr/local/lib/python3.9/dist-packages/openai/_base_client.py", line 1200, in post
    return cast(ResponseT, self.request(cast_to, opts, stream=stream, stream_cls=stream_cls))
  File "/usr/local/lib/python3.9/dist-packages/openai/_base_client.py", line 889, in request
    return self._request(
  File "/usr/local/lib/python3.9/dist-packages/openai/_base_client.py", line 965, in _request
    return self._retry_request(
  File "/usr/local/lib/python3.9/dist-packages/openai/_base_client.py", line 1013, in _retry_request
    return self._request(
  File "/usr/local/lib/python3.9/dist-packages/openai/_base_client.py", line 965, in _request
    return self._retry_request(
  File "/usr/local/lib/python3.9/dist-packages/openai/_base_client.py", line 1013, in _retry_request
    return self._request(
  File "/usr/local/lib/python3.9/dist-packages/openai/_base_client.py", line 980, in _request
    raise self._make_status_error_from_response(err.response) from None
openai.RateLimitError: Error code: 429 - {'error': {'message': 'You exceeded your current quota, please check your plan and billing details. For more information on this error, read the docs: https://platform.openai.com/docs/guides/error-codes/api-errors.', 'type': 'insufficient_quota', 'param': None, 'code': 'insufficient_quota'}}
192.168.0.181 - - [08/Feb/2024 13:54:49] "[36mGET /?__debugger__=yes&cmd=resource&f=style.css HTTP/1.1[0m" 304 -
192.168.0.181 - - [08/Feb/2024 13:54:49] "[36mGET /?__debugger__=yes&cmd=resource&f=debugger.js HTTP/1.1[0m" 304 -
192.168.0.181 - - [08/Feb/2024 13:54:49] "[36mGET /?__debugger__=yes&cmd=resource&f=console.png HTTP/1.1[0m" 304 -
192.168.0.181 - - [08/Feb/2024 13:54:49] "[36mGET /?__debugger__=yes&cmd=resource&f=console.png HTTP/1.1[0m" 304 -
192.168.0.181 - - [08/Feb/2024 14:04:14] "[35m[1mPOST / HTTP/1.1[0m" 500 -
Traceback (most recent call last):
  File "/usr/local/lib/python3.9/dist-packages/flask/app.py", line 1488, in __call__
    return self.wsgi_app(environ, start_response)
  File "/usr/local/lib/python3.9/dist-packages/flask/app.py", line 1466, in wsgi_app
    response = self.handle_exception(e)
  File "/usr/local/lib/python3.9/dist-packages/flask/app.py", line 1463, in wsgi_app
    response = self.full_dispatch_request()
  File "/usr/local/lib/python3.9/dist-packages/flask/app.py", line 872, in full_dispatch_request
    rv = self.handle_user_exception(e)
  File "/usr/local/lib/python3.9/dist-packages/flask/app.py", line 870, in full_dispatch_request
    rv = self.dispatch_request()
  File "/usr/local/lib/python3.9/dist-packages/flask/app.py", line 855, in dispatch_request
    return self.ensure_sync(self.view_functions[rule.endpoint])(**view_args)  # type: ignore[no-any-return]
  File "/root/app.py", line 25, in home
    response = client.chat.completions.create(model="gpt-3.5-turbo",
  File "/usr/local/lib/python3.9/dist-packages/openai/_utils/_utils.py", line 271, in wrapper
    return func(*args, **kwargs)
  File "/usr/local/lib/python3.9/dist-packages/openai/resources/chat/completions.py", line 659, in create
    return self._post(
  File "/usr/local/lib/python3.9/dist-packages/openai/_base_client.py", line 1200, in post
    return cast(ResponseT, self.request(cast_to, opts, stream=stream, stream_cls=stream_cls))
  File "/usr/local/lib/python3.9/dist-packages/openai/_base_client.py", line 889, in request
    return self._request(
  File "/usr/local/lib/python3.9/dist-packages/openai/_base_client.py", line 965, in _request
    return self._retry_request(
  File "/usr/local/lib/python3.9/dist-packages/openai/_base_client.py", line 1013, in _retry_request
    return self._request(
  File "/usr/local/lib/python3.9/dist-packages/openai/_base_client.py", line 965, in _request
    return self._retry_request(
  File "/usr/local/lib/python3.9/dist-packages/openai/_base_client.py", line 1013, in _retry_request
    return self._request(
  File "/usr/local/lib/python3.9/dist-packages/openai/_base_client.py", line 980, in _request
    raise self._make_status_error_from_response(err.response) from None
openai.RateLimitError: Error code: 429 - {'error': {'message': 'You exceeded your current quota, please check your plan and billing details. For more information on this error, read the docs: https://platform.openai.com/docs/guides/error-codes/api-errors.', 'type': 'insufficient_quota', 'param': None, 'code': 'insufficient_quota'}}
192.168.0.181 - - [08/Feb/2024 14:04:14] "[36mGET /?__debugger__=yes&cmd=resource&f=style.css HTTP/1.1[0m" 304 -
192.168.0.181 - - [08/Feb/2024 14:04:14] "[36mGET /?__debugger__=yes&cmd=resource&f=debugger.js HTTP/1.1[0m" 304 -
192.168.0.181 - - [08/Feb/2024 14:04:14] "[36mGET /?__debugger__=yes&cmd=resource&f=console.png HTTP/1.1[0m" 304 -
192.168.0.181 - - [08/Feb/2024 14:05:34] "GET / HTTP/1.1" 200 -
192.168.0.181 - - [08/Feb/2024 14:05:44] "[35m[1mPOST / HTTP/1.1[0m" 500 -
Traceback (most recent call last):
  File "/usr/local/lib/python3.9/dist-packages/flask/app.py", line 1488, in __call__
    return self.wsgi_app(environ, start_response)
  File "/usr/local/lib/python3.9/dist-packages/flask/app.py", line 1466, in wsgi_app
    response = self.handle_exception(e)
  File "/usr/local/lib/python3.9/dist-packages/flask/app.py", line 1463, in wsgi_app
    response = self.full_dispatch_request()
  File "/usr/local/lib/python3.9/dist-packages/flask/app.py", line 872, in full_dispatch_request
    rv = self.handle_user_exception(e)
  File "/usr/local/lib/python3.9/dist-packages/flask/app.py", line 870, in full_dispatch_request
    rv = self.dispatch_request()
  File "/usr/local/lib/python3.9/dist-packages/flask/app.py", line 855, in dispatch_request
    return self.ensure_sync(self.view_functions[rule.endpoint])(**view_args)  # type: ignore[no-any-return]
  File "/root/app.py", line 25, in home
    response = client.chat.completions.create(model="gpt-3.5-turbo",
  File "/usr/local/lib/python3.9/dist-packages/openai/_utils/_utils.py", line 271, in wrapper
    return func(*args, **kwargs)
  File "/usr/local/lib/python3.9/dist-packages/openai/resources/chat/completions.py", line 659, in create
    return self._post(
  File "/usr/local/lib/python3.9/dist-packages/openai/_base_client.py", line 1200, in post
    return cast(ResponseT, self.request(cast_to, opts, stream=stream, stream_cls=stream_cls))
  File "/usr/local/lib/python3.9/dist-packages/openai/_base_client.py", line 889, in request
    return self._request(
  File "/usr/local/lib/python3.9/dist-packages/openai/_base_client.py", line 965, in _request
    return self._retry_request(
  File "/usr/local/lib/python3.9/dist-packages/openai/_base_client.py", line 1013, in _retry_request
    return self._request(
  File "/usr/local/lib/python3.9/dist-packages/openai/_base_client.py", line 965, in _request
    return self._retry_request(
  File "/usr/local/lib/python3.9/dist-packages/openai/_base_client.py", line 1013, in _retry_request
    return self._request(
  File "/usr/local/lib/python3.9/dist-packages/openai/_base_client.py", line 980, in _request
    raise self._make_status_error_from_response(err.response) from None
openai.RateLimitError: Error code: 429 - {'error': {'message': 'You exceeded your current quota, please check your plan and billing details. For more information on this error, read the docs: https://platform.openai.com/docs/guides/error-codes/api-errors.', 'type': 'insufficient_quota', 'param': None, 'code': 'insufficient_quota'}}
192.168.0.181 - - [08/Feb/2024 14:05:44] "[36mGET /?__debugger__=yes&cmd=resource&f=style.css HTTP/1.1[0m" 304 -
192.168.0.181 - - [08/Feb/2024 14:05:44] "[36mGET /?__debugger__=yes&cmd=resource&f=debugger.js HTTP/1.1[0m" 304 -
192.168.0.181 - - [08/Feb/2024 14:05:44] "[36mGET /?__debugger__=yes&cmd=resource&f=console.png HTTP/1.1[0m" 304 -
192.168.0.181 - - [08/Feb/2024 14:27:27] "GET / HTTP/1.1" 200 -
192.168.0.181 - - [08/Feb/2024 14:28:12] "POST / HTTP/1.1" 200 -
192.168.0.181 - - [09/Feb/2024 01:28:29] "POST / HTTP/1.1" 200 -
192.168.0.181 - - [09/Feb/2024 01:28:30] "[33mGET /favicon.ico HTTP/1.1[0m" 404 -
192.168.0.181 - - [09/Feb/2024 01:28:32] "GET / HTTP/1.1" 200 -
192.168.0.181 - - [09/Feb/2024 01:29:28] "POST / HTTP/1.1" 200 -
 * Detected change in '/root/app.py', reloading
 * Restarting with stat
 * Debugger is active!
 * Debugger PIN: 729-843-404
 * Serving Flask app 'app'
 * Debug mode: on
Address already in use
Port 5000 is in use by another program. Either identify and stop that program, or start the server with a different port.
192.168.0.181 - - [09/Feb/2024 14:18:27] "GET / HTTP/1.1" 200 -
192.168.0.181 - - [09/Feb/2024 14:18:28] "[33mGET /favicon.ico HTTP/1.1[0m" 404 -
192.168.0.181 - - [09/Feb/2024 14:18:30] "GET / HTTP/1.1" 200 -
192.168.0.181 - - [09/Feb/2024 14:18:30] "[33mGET /favicon.ico HTTP/1.1[0m" 404 -
192.168.0.181 - - [09/Feb/2024 14:19:30] "POST / HTTP/1.1" 200 -
192.168.0.181 - - [09/Feb/2024 14:20:16] "POST / HTTP/1.1" 200 -
192.168.0.181 - - [09/Feb/2024 14:20:40] "POST / HTTP/1.1" 200 -
192.168.0.181 - - [09/Feb/2024 14:20:42] "POST / HTTP/1.1" 200 -
 * Detected change in '/root/app.py', reloading
 * Restarting with stat
 * Debugger is active!
 * Debugger PIN: 729-843-404
 * Serving Flask app 'app'
 * Debug mode: on
Address already in use
Port 5000 is in use by another program. Either identify and stop that program, or start the server with a different port.
192.168.0.181 - - [09/Feb/2024 14:33:43] "GET / HTTP/1.1" 200 -
192.168.0.181 - - [09/Feb/2024 14:34:10] "POST / HTTP/1.1" 200 -
 * Detected change in '/root/app.py', reloading
 * Restarting with stat
 * Debugger is active!
 * Debugger PIN: 729-843-404
 * Detected change in '/root/app.py', reloading
 * Restarting with stat
 * Debugger is active!
 * Debugger PIN: 729-843-404
 * Serving Flask app 'app'
 * Debug mode: on
Address already in use
Port 5000 is in use by another program. Either identify and stop that program, or start the server with a different port.
192.168.0.181 - - [09/Feb/2024 14:52:36] "POST / HTTP/1.1" 200 -
192.168.0.181 - - [09/Feb/2024 14:52:36] "[33mGET /favicon.ico HTTP/1.1[0m" 404 -
192.168.0.181 - - [09/Feb/2024 14:52:42] "GET / HTTP/1.1" 200 -
192.168.0.181 - - [09/Feb/2024 14:53:00] "POST / HTTP/1.1" 200 -
192.168.0.181 - - [09/Feb/2024 14:54:16] "POST / HTTP/1.1" 200 -
192.168.0.181 - - [09/Feb/2024 14:56:42] "GET / HTTP/1.1" 200 -
192.168.0.181 - - [09/Feb/2024 14:56:42] "[33mGET /favicon.ico HTTP/1.1[0m" 404 -
192.168.0.181 - - [09/Feb/2024 14:59:18] "POST / HTTP/1.1" 200 -
 * Detected change in '/root/app.py', reloading
 * Restarting with stat
  File "/root/app.py", line 1
    rom flask import Flask, request, render_template, session
        ^
SyntaxError: invalid syntax
  File "/root/app.py", line 1
    rom flask import Flask, request, render_template, session
        ^
SyntaxError: invalid syntax
  File "/root/app.py", line 1
    rom flask import Flask, request, render_template, session
        ^
SyntaxError: invalid syntax
  File "/root/app.py", line 1
    rom flask import Flask, request, render_template, session
        ^
SyntaxError: invalid syntax
 * Serving Flask app 'app'
 * Debug mode: on
[31m[1mWARNING: This is a development server. Do not use it in a production deployment. Use a production WSGI server instead.[0m
 * Running on all addresses (0.0.0.0)
 * Running on http://127.0.0.1:5000
 * Running on http://192.168.0.28:5000
[33mPress CTRL+C to quit[0m
 * Restarting with stat
 * Debugger is active!
 * Debugger PIN: 127-227-588
192.168.0.181 - - [09/Feb/2024 16:21:23] "GET / HTTP/1.1" 200 -
192.168.0.181 - - [09/Feb/2024 16:21:23] "[33mGET /favicon.ico HTTP/1.1[0m" 404 -
 * Detected change in '/root/app.py', reloading
 * Restarting with stat
 * Debugger is active!
 * Debugger PIN: 127-227-588
 * Serving Flask app 'app'
 * Debug mode: on
Address already in use
Port 5000 is in use by another program. Either identify and stop that program, or start the server with a different port.
192.168.0.181 - - [09/Feb/2024 16:23:14] "GET / HTTP/1.1" 200 -
192.168.0.181 - - [09/Feb/2024 16:23:14] "[33mGET /favicon.ico HTTP/1.1[0m" 404 -
192.168.0.181 - - [09/Feb/2024 16:23:37] "[35m[1mPOST / HTTP/1.1[0m" 500 -
Traceback (most recent call last):
  File "/usr/local/lib/python3.9/dist-packages/redis/connection.py", line 264, in connect
    sock = self.retry.call_with_retry(
  File "/usr/local/lib/python3.9/dist-packages/redis/retry.py", line 46, in call_with_retry
    return do()
  File "/usr/local/lib/python3.9/dist-packages/redis/connection.py", line 265, in <lambda>
    lambda: self._connect(), lambda error: self.disconnect(error)
  File "/usr/local/lib/python3.9/dist-packages/redis/connection.py", line 627, in _connect
    raise err
  File "/usr/local/lib/python3.9/dist-packages/redis/connection.py", line 615, in _connect
    sock.connect(socket_address)
ConnectionRefusedError: [Errno 111] Connection refused

During handling of the above exception, another exception occurred:

Traceback (most recent call last):
  File "/usr/local/lib/python3.9/dist-packages/flask/app.py", line 1488, in __call__
    return self.wsgi_app(environ, start_response)
  File "/usr/local/lib/python3.9/dist-packages/flask/app.py", line 1466, in wsgi_app
    response = self.handle_exception(e)
  File "/usr/local/lib/python3.9/dist-packages/flask/app.py", line 1463, in wsgi_app
    response = self.full_dispatch_request()
  File "/usr/local/lib/python3.9/dist-packages/flask/app.py", line 872, in full_dispatch_request
    rv = self.handle_user_exception(e)
  File "/usr/local/lib/python3.9/dist-packages/flask/app.py", line 870, in full_dispatch_request
    rv = self.dispatch_request()
  File "/usr/local/lib/python3.9/dist-packages/flask/app.py", line 855, in dispatch_request
    return self.ensure_sync(self.view_functions[rule.endpoint])(**view_args)  # type: ignore[no-any-return]
  File "/root/app.py", line 50, in home
    response_content = get_cached_response(user_message, session_id)
  File "/root/app.py", line 24, in get_cached_response
    cached_response = cache.get(cache_key)
  File "/usr/local/lib/python3.9/dist-packages/redis/commands/core.py", line 1829, in get
    return self.execute_command("GET", name)
  File "/usr/local/lib/python3.9/dist-packages/redis/client.py", line 533, in execute_command
    conn = self.connection or pool.get_connection(command_name, **options)
  File "/usr/local/lib/python3.9/dist-packages/redis/connection.py", line 1086, in get_connection
    connection.connect()
  File "/usr/local/lib/python3.9/dist-packages/redis/connection.py", line 270, in connect
    raise ConnectionError(self._error_message(e))
redis.exceptions.ConnectionError: Error 111 connecting to localhost:6379. Connection refused.
192.168.0.181 - - [09/Feb/2024 16:23:37] "GET /?__debugger__=yes&cmd=resource&f=style.css HTTP/1.1" 200 -
192.168.0.181 - - [09/Feb/2024 16:23:37] "GET /?__debugger__=yes&cmd=resource&f=debugger.js HTTP/1.1" 200 -
192.168.0.181 - - [09/Feb/2024 16:23:37] "GET /?__debugger__=yes&cmd=resource&f=console.png HTTP/1.1" 200 -
192.168.0.181 - - [09/Feb/2024 16:23:37] "[36mGET /?__debugger__=yes&cmd=resource&f=console.png HTTP/1.1[0m" 304 -
 * Serving Flask app 'app'
 * Debug mode: on
Address already in use
Port 5000 is in use by another program. Either identify and stop that program, or start the server with a different port.
 * Serving Flask app 'app'
 * Debug mode: on
Address already in use
Port 5000 is in use by another program. Either identify and stop that program, or start the server with a different port.
 * Serving Flask app 'app'
 * Debug mode: on
Address already in use
Port 5000 is in use by another program. Either identify and stop that program, or start the server with a different port.
 * Serving Flask app 'app'
 * Debug mode: on
Address already in use
Port 5000 is in use by another program. Either identify and stop that program, or start the server with a different port.
192.168.0.181 - - [09/Feb/2024 16:46:27] "GET / HTTP/1.1" 200 -
192.168.0.181 - - [09/Feb/2024 16:46:57] "POST / HTTP/1.1" 200 -
 * Detected change in '/root/app.py', reloading
 * Restarting with stat
 * Debugger is active!
 * Debugger PIN: 127-227-588
192.168.0.181 - - [09/Feb/2024 17:30:47] "GET / HTTP/1.1" 200 -
192.168.0.181 - - [09/Feb/2024 17:30:50] "GET / HTTP/1.1" 200 -
192.168.0.181 - - [09/Feb/2024 17:30:50] "[33mGET /favicon.ico HTTP/1.1[0m" 404 -
192.168.0.181 - - [09/Feb/2024 17:30:51] "GET / HTTP/1.1" 200 -
192.168.0.181 - - [09/Feb/2024 17:30:51] "[33mGET /favicon.ico HTTP/1.1[0m" 404 -
192.168.0.181 - - [09/Feb/2024 17:30:51] "GET / HTTP/1.1" 200 -
192.168.0.181 - - [09/Feb/2024 17:30:51] "[33mGET /favicon.ico HTTP/1.1[0m" 404 -
192.168.0.181 - - [09/Feb/2024 17:30:51] "GET / HTTP/1.1" 200 -
192.168.0.181 - - [09/Feb/2024 17:30:51] "[33mGET /favicon.ico HTTP/1.1[0m" 404 -
192.168.0.181 - - [09/Feb/2024 17:30:52] "GET / HTTP/1.1" 200 -
192.168.0.181 - - [09/Feb/2024 17:30:52] "[33mGET /favicon.ico HTTP/1.1[0m" 404 -
192.168.0.181 - - [09/Feb/2024 17:30:52] "GET / HTTP/1.1" 200 -
192.168.0.181 - - [09/Feb/2024 17:30:52] "[33mGET /favicon.ico HTTP/1.1[0m" 404 -
192.168.0.181 - - [09/Feb/2024 17:30:52] "GET / HTTP/1.1" 200 -
192.168.0.181 - - [09/Feb/2024 17:30:52] "[33mGET /favicon.ico HTTP/1.1[0m" 404 -
192.168.0.181 - - [09/Feb/2024 17:31:04] "POST / HTTP/1.1" 200 -
192.168.0.181 - - [09/Feb/2024 17:31:28] "POST / HTTP/1.1" 200 -
192.168.0.181 - - [09/Feb/2024 17:31:34] "POST / HTTP/1.1" 200 -
192.168.0.181 - - [09/Feb/2024 17:31:41] "POST / HTTP/1.1" 200 -
192.168.0.181 - - [09/Feb/2024 17:31:47] "POST / HTTP/1.1" 200 -
192.168.0.181 - - [09/Feb/2024 17:31:48] "[33mGET /favicon.ico HTTP/1.1[0m" 404 -
192.168.0.181 - - [09/Feb/2024 17:31:50] "GET / HTTP/1.1" 200 -
192.168.0.181 - - [11/Feb/2024 13:30:29] "GET / HTTP/1.1" 200 -
192.168.0.181 - - [11/Feb/2024 13:30:29] "[33mGET /favicon.ico HTTP/1.1[0m" 404 -
192.168.0.181 - - [11/Feb/2024 13:33:21] "POST / HTTP/1.1" 200 -
192.168.0.181 - - [11/Feb/2024 13:34:25] "POST / HTTP/1.1" 200 -
 * Serving Flask app 'app'
 * Debug mode: on
Address already in use
Port 5000 is in use by another program. Either identify and stop that program, or start the server with a different port.
 * Debug mode: off
[31m[1mWARNING: This is a development server. Do not use it in a production deployment. Use a production WSGI server instead.[0m
 * Running on http://127.0.0.1:5001
[33mPress CTRL+C to quit[0m
